Workbook

Sheet Remplissage - Sit. Init.
A1: Catégorie | C1: Sous-catégorie | D1: Titre | E1: Description | F1: Nom de la variable | G1: Type | H1: Affichage | I1: Valeur | J1: Valeurs possibles | K1: Unité | L1: Valeur par défaut | M1: Commentaire | N1: Action(s) liée(s) | O1: Affichage à la création
A2: Données de base | D2: Année de remplissage des données | F2: AnneeRempl | G2: number | H2: 1 | I2: 2024 | O2: 1
A3: Données de base | D3: Nom du territoire | F3: NomTerr | G3: text | H3: 1 | I3: Nantes Métropole;Communauté de communes du Gâtinais en Bourgogne;Communauté de communes du Vexin-Val de Seine | M3: Ajouter la possibilité d'avoir une liste déroulante complétant au fur et à mesure, selon les noms d'EPCI de la colone libgeo de l'onglet Données génériques EPCI_2023, séparer par un ";" | O3: 1
A4: Données de base | D4: SIREN territoire | F4: SIRENTerr | G4: number | H4: 0 | I4: 999999999
A5: Données de base | D5: Nombre d'habitants | F5: NbHabTerr | G5: number | H5: 1 | I5: 695932.39 | K5: hab | L5: #REF!
A6: Données de base | D6: Nombre de ménages | F6: NbMenTerr | G6: number | H6: 1 | I6: 330067.81 | K6: ménages | L6: #REF!
A7: Données de base | D7: Superficie | F7: SupTerr | G7: number | H7: 1 | I7: 523.2 | K7: km² | L7: #REF!
A8: Données de base | D8: Typologie de territoire | F8: TypoTerr | G8: radio | H8: 1 | I8: Territoire polarisé autour d'une commune centre | J8: Territoire polarisé autour d'une commune centre,Territoire polarisé autour de plusieurs communes
A9: Données de base | D9: Nombre de communes "pôles" | F9: NbPolesTerr | G9: number | H9: =IF(I8="Territoire polarisé autour de plusieurs communes",1,0) -> 0 | K9: pôles
A10: Données de base | D10: Nombre d'habitants dans la commune pôle n°1 | F10: NbHabPole1 | G10: number | H10: 1 | I10: 50000 | K10: hab
A11: Données de base | D11: Nombre d'habitants dans la commune pôle n°2 | F11: NbHabPole2 | G11: number | H11: =IF($I$9>1,1,0) -> 0 | K11: hab
A12: Données de base | D12: Nombre d'habitants dans la commune pôle n°3 | F12: NbHabPole3 | G12: number | H12: =IF($I$9>2,1,0) -> 0 | K12: hab
A13: Données de base | D13: Nombre d'habitants dans la commune pôle n°4 | F13: NbHabPole4 | G13: number | H13: =IF($I$9>3,1,0) -> 0 | K13: hab
A14: Données de base | D14: Nombre d'habitants dans la commune pôle n°5 | F14: NbHabPole5 | G14: number | H14: =IF($I$9>4,1,0) -> 0 | K14: hab
A15: Données de base | D15: Possibilité et intention de développement du fret fluvial ? | F15: FretFluv | G15: radio | H15: 1 | I15: Oui | J15: Oui,Non
A16: Données de base | D16: Possibilité et intention de développement du fret ferroviaire ? | F16: FretFerr | G16: radio | H16: 1 | I16: Oui | J16: Oui,Non
A17: Données de base | D17: Sélectionnez les actions du catalogue d'actions InTerLUD+ se rapprochant d'actions dont la mise en œuvre avait commencé en amont de l'engagement de votre territoire dans la démarche InTerLUD+ | F17: ActionsAutres | G17: checkbox | H17: 1 | I17: A1,A2,A3,B1,B3,B4,B5,C1,C2,C3,C4,C5,C6,C7,C8,C9 | J17: A1,A2,A3,B1,B2,B3,B4,B5,C1,C2,C3,C4,C5,C6,C7,C8,C9 | O17: 1
A18: Données de base | D18: Sélectionnez les actions du catalogue d'actions InTerLUD+ se rapprochant d'actions inscrites dans votre charte | F18: ActionsCharte | G18: checkbox | H18: 1 | I18: A1,A2,A3,B1,B3,B4,B5,C1,C2,C3,C4,C5,C6,C7,C8,C9 | J18: A1,A2,A3,B1,B2,B3,B4,B5,C1,C2,C3,C4,C5,C6,C7,C8,C9 | O18: 1
A19: Données de production/consommation d'énergie | D19: Y-a-t-il une ou plusieurs stations d'avitaillement GNV sur votre territoire ? | F19: GNV | G19: radio | H19: 1 | I19: Oui | J19: Oui,Non
A20: Données de production/consommation d'énergie | D20: Quelle est la part de bioGNV dans le GNV distribué dans cette ou ces stations d'avitaillement ? | F20: bioGNV | G20: number | H20: =IF(I19="Oui",1,0) -> 1 | I20: 0.3 | K20: % | L20: #REF!
A21: Données de production/consommation d'énergie | D21: Y-a-t-il une ou plusieurs stations d'avitaillement hydrogène sur votre territoire ? | F21: H2 | G21: radio | H21: 1 | I21: 80 | J21: Oui,Non
A22: Données de production/consommation d'énergie | D22: Origine de l'hydrogène utilisé | F22: H2Vert | G22: number | H22: =IF(I21="Oui",1,0) -> 0 | J22: Hydrogène produit à partir d'électricité renouvelable,Hydrogène produit à partir de biométhane,Hydrogène produit à partir de ressources fossiles
A23: Fret routier | C23: Catégorie 1 | D23: Nom de la catégorie de véhicules | F23: =_xlfn.CONCAT("FretRout",LEFT(C23,3),RIGHT(C23,1),"Nom") -> FretRoutCat1Nom | G23: text | H23: 1 | J23: VUL Electrique (Crit'Air E) | L23: =J23 -> VUL Electrique (Crit'Air E)
A24: Fret routier | C24: Catégorie 1 | D24: Type de véhicule | F24: =_xlfn.CONCAT("FretRout",LEFT(C24,3),RIGHT(C24,1),"Type") -> FretRoutCat1Type | G24: text | H24: 1 | J24: VUL | L24: =J24 -> VUL
A25: Fret routier | C25: Catégorie 1 | D25: PTAC | F25: =_xlfn.CONCAT("FretRout",LEFT(C25,3),RIGHT(C25,1),"PTAC") -> FretRoutCat1PTAC | G25: radio | H25: 1 | J25: <=3,5t | L25: =J25 -> <=3,5t
A26: Fret routier | C26: Catégorie 1 | D26: Motorisation | F26: =_xlfn.CONCAT("FretRout",LEFT(C26,3),RIGHT(C26,1),"Mot") -> FretRoutCat1Mot | G26: radio | H26: 1 | J26: Electrique | L26: =J26 -> Electrique
A27: Fret routier | C27: Catégorie 1 | D27: Carburant utilisé | F27: =_xlfn.CONCAT("FretRout",LEFT(C27,3),RIGHT(C27,1),"Carb") -> FretRoutCat1Carb | G27: radio | H27: 1 | J27: - | L27: =J27 -> -
A28: Fret routier | C28: Catégorie 1 | D28: Norme Euro | F28: =_xlfn.CONCAT("FretRout",LEFT(C28,3),RIGHT(C28,1),"Euro") -> FretRoutCat1Euro | G28: radio | H28: 1 | J28: 0 | L28: =J28 -> 0
A29: Fret routier | C29: Catégorie 1 | D29: Vignette Crit'Air | F29: =_xlfn.CONCAT("FretRout",LEFT(C29,3),RIGHT(C29,1),"CritAir") -> FretRoutCat1CritAir | G29: radio | H29: 1 | J29: E | L29: =J29 -> E
A30: Fret routier | C30: Catégorie 1 | D30: Nombre de véhicules correspondants | F30: =_xlfn.CONCAT("FretRout",LEFT(C30,3),RIGHT(C30,1),"Nb") -> FretRoutCat1Nb | G30: number | H30: 1 | K30: véhicules | L30: 0
A31: Fret routier | C31: Catégorie 1 | D31: Ordre de grandeur de la distance parcourue annuellement (ensemble des véhicules renseignés pour la catégorie) | F31: =_xlfn.CONCAT("FretRout",LEFT(C31,3),RIGHT(C31,1),"Dist") -> FretRoutCat1Dist | G31: number | H31: 1 | K31: km | L31: 7694
A32: Fret routier | C32: Catégorie 1 | D32: Estimation du taux de remplissage moyen de ces véhicules | F32: =_xlfn.CONCAT("FretRout",LEFT(C32,3),RIGHT(C32,1),"Rempl") -> FretRoutCat1Rempl | G32: number | H32: 1 | K32: % | L32: 0
A33: Fret routier | C33: Catégorie 2 | D33: Nom de la catégorie de véhicules | F33: =_xlfn.CONCAT("FretRout",LEFT(C33,3),RIGHT(C33,1),"Nom") -> FretRoutCat2Nom | G33: text | H33: 1 | J33: VUL Diesel (Crit'Air 2) | L33: =J33 -> VUL Diesel (Crit'Air 2)
A34: Fret routier | C34: Catégorie 2 | D34: Type de véhicule | F34: =_xlfn.CONCAT("FretRout",LEFT(C34,3),RIGHT(C34,1),"Type") -> FretRoutCat2Type | G34: text | H34: 1 | J34: VUL | L34: =J34 -> VUL
A35: Fret routier | C35: Catégorie 2 | D35: PTAC | F35: =_xlfn.CONCAT("FretRout",LEFT(C35,3),RIGHT(C35,1),"PTAC") -> FretRoutCat2PTAC | G35: radio | H35: 1 | J35: <=3,5t | L35: =J35 -> <=3,5t
A36: Fret routier | C36: Catégorie 2 | D36: Motorisation | F36: =_xlfn.CONCAT("FretRout",LEFT(C36,3),RIGHT(C36,1),"Mot") -> FretRoutCat2Mot | G36: radio | H36: 1 | J36: Diesel | L36: =J36 -> Diesel
A37: Fret routier | C37: Catégorie 2 | D37: Carburant utilisé | F37: =_xlfn.CONCAT("FretRout",LEFT(C37,3),RIGHT(C37,1),"Carb") -> FretRoutCat2Carb | G37: radio | H37: 1 | J37: Gazole à la pompe | L37: =J37 -> Gazole à la pompe
A38: Fret routier | C38: Catégorie 2 | D38: Norme Euro | F38: =_xlfn.CONCAT("FretRout",LEFT(C38,3),RIGHT(C38,1),"Euro") -> FretRoutCat2Euro | G38: radio | H38: 1 | J38: 0 | L38: =J38 -> 0
A39: Fret routier | C39: Catégorie 2 | D39: Vignette Crit'Air | F39: =_xlfn.CONCAT("FretRout",LEFT(C39,3),RIGHT(C39,1),"CritAir") -> FretRoutCat2CritAir | G39: radio | H39: 1 | J39: 2 | L39: =J39 -> 2
A40: Fret routier | C40: Catégorie 2 | D40: Nombre de véhicules correspondants | F40: =_xlfn.CONCAT("FretRout",LEFT(C40,3),RIGHT(C40,1),"Nb") -> FretRoutCat2Nb | G40: number | H40: 1 | K40: véhicules | L40: 0
...

Sheet List
B3: VUL Electrique (Crit'Air E)
B4: VUL Electrique (Crit'Air E)
B5: VUL Diesel (Crit'Air 2)
B6: VUL Diesel (Crit'Air 2)
B7: VUL Diesel (Crit'Air 3)
B8: VUL Diesel (Crit'Air 3)
B9: VUL Diesel (Crit'Air 4)
B10: VUL Diesel (Crit'Air 4)
B11: VUL Diesel (Crit'Air 5)
B12: VUL Diesel (Crit'Air 5)
B13: VUL Essence (Crit'Air 1)
B14: VUL Essence (Crit'Air 1)
... B92: PL Gaz (GNC) >28-34t (Crit'Air 2)

Sheet Remplissage - Sit. Ref.
A1: Catégorie | B1: Sous-catégorie | C1: Titre | D1: Description | E1: Nom de la variable | F1: Type | G1: Affichage | H1: Valeur | I1: Valeurs possibles | J1: Unité | K1: Valeur par défaut | L1: Commentaire | M1: Action(s) liée(s) | N1: Affichage à la création | P1: 2024 | Q1: 2025 | R1: 2026 | S1: 2027 | T1: 2028 | U1: 2029 | V1: 2030 | W1: 2031 | X1: 2032 | Y1: 2033 | Z1: 2034 | AA1: 2035 | AB1: 2036 | AC1: 2037 | AD1: 2038 | AE1: 2039 | AF1: 2040 | AG1: 2041 | AH1: 2042 | AI1: 2043 | AJ1: 2044 | AK1: 2045 | AL1: 2046 | AM1: 2047 | AN1: 2048 | AO1: 2049 | AP1: 2050
A2: Généralités | C2: Année de la situation de référence | E2: AnRef | F2: number | G2: 1 | H2: 2028
A3: Généralités | C3: Projection de population | E3: ProjPop | F3: number | G3: 1 | H3: 721036.16 | J3: hab | K3: #REF!
A4: Généralités | C4: Projection de nombre de ménages | E4: ProjMen | F4: number | G4: 1 | H4: 341974.06 | J4: ménages | K4: #REF!
A5: Données de production/consommation d'énergie | C5: Part de bioGNV distribuée sur le territoire | E5: bioGNV | F5: number | G5: 1 | H5: 0.3 | J5: % | K5: #REF!
A6: Fret routier | B6: Catégorie 1 | C6: Nom de la catégorie de véhicules | E6: =_xlfn.CONCAT("FretRout",LEFT(B6,3),RIGHT(B6,1),"Nom") -> FretRoutCat1Nom | F6: text | G6: 1 | H6: 34 | I6: VUL Electrique (Crit'Air E) | K6: =I6 -> VUL Electrique (Crit'Air E)
A7: Fret routier | B7: Catégorie 1 | C7: Type de véhicule | E7: =_xlfn.CONCAT("FretRout",LEFT(B7,3),RIGHT(B7,1),"Type") -> FretRoutCat1Type | F7: text | G7: 1 | I7: VUL | K7: =I7 -> VUL
A8: Fret routier | B8: Catégorie 1 | C8: PTAC | E8: =_xlfn.CONCAT("FretRout",LEFT(B8,3),RIGHT(B8,1),"PTAC") -> FretRoutCat1PTAC | F8: radio | G8: 1 | I8: <=3,5t | K8: =I8 -> <=3,5t
A9: Fret routier | B9: Catégorie 1 | C9: Motorisation | E9: =_xlfn.CONCAT("FretRout",LEFT(B9,3),RIGHT(B9,1),"Mot") -> FretRoutCat1Mot | F9: radio | G9: 1 | I9: Electrique | K9: =I9 -> Electrique
A10: Fret routier | B10: Catégorie 1 | C10: Carburant utilisé | E10: =_xlfn.CONCAT("FretRout",LEFT(B10,3),RIGHT(B10,1),"Carb") -> FretRoutCat1Carb | F10: radio | G10: 1 | I10: - | K10: =I10 -> -
A11: Fret routier | B11: Catégorie 1 | C11: Norme Euro | E11: =_xlfn.CONCAT("FretRout",LEFT(B11,3),RIGHT(B11,1),"Euro") -> FretRoutCat1Euro | F11: radio | G11: 1 | I11: 0 | K11: =I11 -> 0 | Q11: #REF! | R11: =(6*VLOOKUP($H7&";TauxRenouvellement",#REF!,R$1-2020,FALSE)*VLOOKUP($H7&";Volume",#REF!,R$1-2020,FALSE)+ Q11*(VLOOKUP($H7&";Volume",#REF!,R$1-2019,FALSE)-VLOOKUP($H7&";TauxRenouvellement",#REF!,R$1-2020,FALSE)*VLOOKUP($H7&";Volume",#REF!,R$1-2020,FALSE)))/ VLOOKUP($H7&";Volume",#REF!,R$1-2019,FALSE) -> #REF! | S11: =(6*VLOOKUP($H7&";TauxRenouvellement",#REF!,S$1-2020,FALSE)*VLOOKUP($H7&";Volume",#REF!,S$1-2020,FALSE)+ R11*(VLOOKUP($H7&";Volume",#REF!,S$1-2019,FALSE)-VLOOKUP($H7&";TauxRenouvellement",#REF!,S$1-2020,FALSE)*VLOOKUP($H7&";Volume",#REF!,S$1-2020,FALSE)))/ VLOOKUP($H7&";Volume",#REF!,S$1-2019,FALSE) -> #REF! | T11: =(6*VLOOKUP($H7&";TauxRenouvellement",#REF!,T$1-2020,FALSE)*VLOOKUP($H7&";Volume",#REF!,T$1-2020,FALSE)+ S11*(VLOOKUP($H7&";Volume",#REF!,T$1-2019,FALSE)-VLOOKUP($H7&";TauxRenouvellement",#REF!,T$1-2020,FALSE)*VLOOKUP($H7&";Volume",#REF!,T$1-2020,FALSE)))/ VLOOKUP($H7&";Volume",#REF!,T$1-2019,FALSE) -> #REF! | U11: =(6*VLOOKUP($H7&";TauxRenouvellement",#REF!,U$1-2020,FALSE)*VLOOKUP($H7&";Volume",#REF!,U$1-2020,FALSE)+ T11*(VLOOKUP($H7&";Volume",#REF!,U$1-2019,FALSE)-VLOOKUP($H7&";TauxRenouvellement",#REF!,U$1-2020,FALSE)*VLOOKUP($H7&";Volume",#REF!,U$1-2020,FALSE)))/ VLOOKUP($H7&";Volume",#REF!,U$1-2019,FALSE) -> #REF! | V11: =(6*VLOOKUP($H7&";TauxRenouvellement",#REF!,V$1-2020,FALSE)*VLOOKUP($H7&";Volume",#REF!,V$1-2020,FALSE)+ U11*(VLOOKUP($H7&";Volume",#REF!,V$1-2019,FALSE)-VLOOKUP($H7&";TauxRenouvellement",#REF!,V$1-2020,FALSE)*VLOOKUP($H7&";Volume",#REF!,V$1-2020,FALSE)))/ VLOOKUP($H7&";Volume",#REF!,V$1-2019,FALSE) -> #REF! | W11: =(6*VLOOKUP($H7&";TauxRenouvellement",#REF!,W$1-2020,FALSE)*VLOOKUP($H7&";Volume",#REF!,W$1-2020,FALSE)+ V11*(VLOOKUP($H7&";Volume",#REF!,W$1-2019,FALSE)-VLOOKUP($H7&";TauxRenouvellement",#REF!,W$1-2020,FALSE)*VLOOKUP($H7&";Volume",#REF!,W$1-2020,FALSE)))/ VLOOKUP($H7&";Volume",#REF!,W$1-2019,FALSE) -> #REF! | X11: =(6*VLOOKUP($H7&";TauxRenouvellement",#REF!,X$1-2020,FALSE)*VLOOKUP($H7&";Volume",#REF!,X$1-2020,FALSE)+ W11*(VLOOKUP($H7&";Volume",#REF!,X$1-2019,FALSE)-VLOOKUP($H7&";TauxRenouvellement",#REF!,X$1-2020,FALSE)*VLOOKUP($H7&";Volume",#REF!,X$1-2020,FALSE)))/ VLOOKUP($H7&";Volume",#REF!,X$1-2019,FALSE) -> #REF! | Y11: =(6*VLOOKUP($H7&";TauxRenouvellement",#REF!,Y$1-2020,FALSE)*VLOOKUP($H7&";Volume",#REF!,Y$1-2020,FALSE)+ X11*(VLOOKUP($H7&";Volume",#REF!,Y$1-2019,FALSE)-VLOOKUP($H7&";TauxRenouvellement",#REF!,Y$1-2020,FALSE)*VLOOKUP($H7&";Volume",#REF!,Y$1-2020,FALSE)))/ VLOOKUP($H7&";Volume",#REF!,Y$1-2019,FALSE) -> #REF! | ... AP11: =(6*VLOOKUP($H7&";TauxRenouvellement",#REF!,AP$1-2020,FALSE)*VLOOKUP($H7&";Volume",#REF!,AP$1-2020,FALSE)+ AO11*(VLOOKUP($H7&";Volume",#REF!,AP$1-2019,FALSE)-VLOOKUP($H7&";TauxRenouvellement",#REF!,AP$1-2020,FALSE)*VLOOKUP($H7&";Volume",#REF!,AP$1-2020,FALSE)))/ VLOOKUP($H7&";Volume",#REF!,AP$1-2019,FALSE) -> #REF!
A12: Fret routier | B12: Catégorie 1 | C12: Vignette Crit'Air | E12: =_xlfn.CONCAT("FretRout",LEFT(B12,3),RIGHT(B12,1),"CritAir") -> FretRoutCat1CritAir | F12: radio | G12: 1 | I12: E | K12: =I12 -> E | Q12: #REF! | R12: =(VLOOKUP($H7&";TauxRenouvellement",#REF!,R$1-2020,FALSE)*VLOOKUP($H7&";Volume",#REF!,R$1-2020,FALSE)+ Q12*(VLOOKUP($H7&";Volume",#REF!,R$1-2019,FALSE)-VLOOKUP($H7&";TauxRenouvellement",#REF!,R$1-2020,FALSE)*VLOOKUP($H7&";Volume",#REF!,R$1-2020,FALSE)))/ VLOOKUP($H7&";Volume",#REF!,R$1-2019,FALSE) -> #REF! | S12: =(VLOOKUP($H7&";TauxRenouvellement",#REF!,S$1-2020,FALSE)*VLOOKUP($H7&";Volume",#REF!,S$1-2020,FALSE)+ R12*(VLOOKUP($H7&";Volume",#REF!,S$1-2019,FALSE)-VLOOKUP($H7&";TauxRenouvellement",#REF!,S$1-2020,FALSE)*VLOOKUP($H7&";Volume",#REF!,S$1-2020,FALSE)))/ VLOOKUP($H7&";Volume",#REF!,S$1-2019,FALSE) -> #REF! | T12: =(VLOOKUP($H7&";TauxRenouvellement",#REF!,T$1-2020,FALSE)*VLOOKUP($H7&";Volume",#REF!,T$1-2020,FALSE)+ S12*(VLOOKUP($H7&";Volume",#REF!,T$1-2019,FALSE)-VLOOKUP($H7&";TauxRenouvellement",#REF!,T$1-2020,FALSE)*VLOOKUP($H7&";Volume",#REF!,T$1-2020,FALSE)))/ VLOOKUP($H7&";Volume",#REF!,T$1-2019,FALSE) -> #REF! | U12: =(VLOOKUP($H7&";TauxRenouvellement",#REF!,U$1-2020,FALSE)*VLOOKUP($H7&";Volume",#REF!,U$1-2020,FALSE)+ T12*(VLOOKUP($H7&";Volume",#REF!,U$1-2019,FALSE)-VLOOKUP($H7&";TauxRenouvellement",#REF!,U$1-2020,FALSE)*VLOOKUP($H7&";Volume",#REF!,U$1-2020,FALSE)))/ VLOOKUP($H7&";Volume",#REF!,U$1-2019,FALSE) -> #REF! | V12: =(VLOOKUP($H7&";TauxRenouvellement",#REF!,V$1-2020,FALSE)*VLOOKUP($H7&";Volume",#REF!,V$1-2020,FALSE)+ U12*(VLOOKUP($H7&";Volume",#REF!,V$1-2019,FALSE)-VLOOKUP($H7&";TauxRenouvellement",#REF!,V$1-2020,FALSE)*VLOOKUP($H7&";Volume",#REF!,V$1-2020,FALSE)))/ VLOOKUP($H7&";Volume",#REF!,V$1-2019,FALSE) -> #REF! | W12: =(VLOOKUP($H7&";TauxRenouvellement",#REF!,W$1-2020,FALSE)*VLOOKUP($H7&";Volume",#REF!,W$1-2020,FALSE)+ V12*(VLOOKUP($H7&";Volume",#REF!,W$1-2019,FALSE)-VLOOKUP($H7&";TauxRenouvellement",#REF!,W$1-2020,FALSE)*VLOOKUP($H7&";Volume",#REF!,W$1-2020,FALSE)))/ VLOOKUP($H7&";Volume",#REF!,W$1-2019,FALSE) -> #REF! | X12: =(VLOOKUP($H7&";TauxRenouvellement",#REF!,X$1-2020,FALSE)*VLOOKUP($H7&";Volume",#REF!,X$1-2020,FALSE)+ W12*(VLOOKUP($H7&";Volume",#REF!,X$1-2019,FALSE)-VLOOKUP($H7&";TauxRenouvellement",#REF!,X$1-2020,FALSE)*VLOOKUP($H7&";Volume",#REF!,X$1-2020,FALSE)))/ VLOOKUP($H7&";Volume",#REF!,X$1-2019,FALSE) -> #REF! | Y12: =(VLOOKUP($H7&";TauxRenouvellement",#REF!,Y$1-2020,FALSE)*VLOOKUP($H7&";Volume",#REF!,Y$1-2020,FALSE)+ X12*(VLOOKUP($H7&";Volume",#REF!,Y$1-2019,FALSE)-VLOOKUP($H7&";TauxRenouvellement",#REF!,Y$1-2020,FALSE)*VLOOKUP($H7&";Volume",#REF!,Y$1-2020,FALSE)))/ VLOOKUP($H7&";Volume",#REF!,Y$1-2019,FALSE) -> #REF! | ... AP12: =(VLOOKUP($H7&";TauxRenouvellement",#REF!,AP$1-2020,FALSE)*VLOOKUP($H7&";Volume",#REF!,AP$1-2020,FALSE)+ AO12*(VLOOKUP($H7&";Volume",#REF!,AP$1-2019,FALSE)-VLOOKUP($H7&";TauxRenouvellement",#REF!,AP$1-2020,FALSE)*VLOOKUP($H7&";Volume",#REF!,AP$1-2020,FALSE)))/ VLOOKUP($H7&";Volume",#REF!,AP$1-2019,FALSE) -> #REF!
A13: Fret routier | B13: Catégorie 1 | C13: Nombre de véhicules correspondants | E13: =_xlfn.CONCAT("FretRout",LEFT(B13,3),RIGHT(B13,1),"Nb") -> FretRoutCat1Nb | F13: number | G13: 1 | J13: véhicules | K13: 0
A14: Fret routier | B14: Catégorie 1 | C14: Ordre de grandeur de la distance parcourue annuellement (ensemble des véhicules renseignés pour la catégorie) | E14: =_xlfn.CONCAT("FretRout",LEFT(B14,3),RIGHT(B14,1),"Dist") -> FretRoutCat1Dist | F14: number | G14: 1 | J14: km | K14: 7694
A15: Fret routier | B15: Catégorie 1 | C15: Estimation du taux de remplissage moyen de ces véhicules | E15: =_xlfn.CONCAT("FretRout",LEFT(B15,3),RIGHT(B15,1),"Rempl") -> FretRoutCat1Rempl | F15: number | G15: 1 | H15: X | J15: % | K15: 0
A16: Fret routier | B16: Catégorie 2 | C16: Nom de la catégorie de véhicules | E16: =_xlfn.CONCAT("FretRout",LEFT(B16,3),RIGHT(B16,1),"Nom") -> FretRoutCat2Nom | F16: text | G16: 1 | H16: 45 | I16: VUL Diesel (Crit'Air 2) | K16: =I16 -> VUL Diesel (Crit'Air 2)
A17: Fret routier | B17: Catégorie 2 | C17: Type de véhicule | E17: =_xlfn.CONCAT("FretRout",LEFT(B17,3),RIGHT(B17,1),"Type") -> FretRoutCat2Type | F17: text | G17: 1 | I17: VUL | K17: =I17 -> VUL
A18: Fret routier | B18: Catégorie 2 | C18: PTAC | E18: =_xlfn.CONCAT("FretRout",LEFT(B18,3),RIGHT(B18,1),"PTAC") -> FretRoutCat2PTAC | F18: radio | G18: 1 | I18: <=3,5t | K18: =I18 -> <=3,5t
A19: Fret routier | B19: Catégorie 2 | C19: Motorisation | E19: =_xlfn.CONCAT("FretRout",LEFT(B19,3),RIGHT(B19,1),"Mot") -> FretRoutCat2Mot | F19: radio | G19: 1 | I19: Diesel | K19: =I19 -> Diesel
A20: Fret routier | B20: Catégorie 2 | C20: Carburant utilisé | E20: =_xlfn.CONCAT("FretRout",LEFT(B20,3),RIGHT(B20,1),"Carb") -> FretRoutCat2Carb | F20: radio | G20: 1 | I20: Gazole à la pompe | K20: =I20 -> Gazole à la pompe
A21: Fret routier | B21: Catégorie 2 | C21: Norme Euro | E21: =_xlfn.CONCAT("FretRout",LEFT(B21,3),RIGHT(B21,1),"Euro") -> FretRoutCat2Euro | F21: radio | G21: 1 | I21: 0 | K21: =I21 -> 0 | Q21: #REF! | R21: =(6*VLOOKUP($H17&";TauxRenouvellement",#REF!,R$1-2020,FALSE)*VLOOKUP($H17&";Volume",#REF!,R$1-2020,FALSE)+ Q21*(VLOOKUP($H17&";Volume",#REF!,R$1-2019,FALSE)-VLOOKUP($H17&";TauxRenouvellement",#REF!,R$1-2020,FALSE)*VLOOKUP($H17&";Volume",#REF!,R$1-2020,FALSE)))/ VLOOKUP($H17&";Volume",#REF!,R$1-2019,FALSE) -> #REF! | S21: =(6*VLOOKUP($H17&";TauxRenouvellement",#REF!,S$1-2020,FALSE)*VLOOKUP($H17&";Volume",#REF!,S$1-2020,FALSE)+ R21*(VLOOKUP($H17&";Volume",#REF!,S$1-2019,FALSE)-VLOOKUP($H17&";TauxRenouvellement",#REF!,S$1-2020,FALSE)*VLOOKUP($H17&";Volume",#REF!,S$1-2020,FALSE)))/ VLOOKUP($H17&";Volume",#REF!,S$1-2019,FALSE) -> #REF! | T21: =(6*VLOOKUP($H17&";TauxRenouvellement",#REF!,T$1-2020,FALSE)*VLOOKUP($H17&";Volume",#REF!,T$1-2020,FALSE)+ S21*(VLOOKUP($H17&";Volume",#REF!,T$1-2019,FALSE)-VLOOKUP($H17&";TauxRenouvellement",#REF!,T$1-2020,FALSE)*VLOOKUP($H17&";Volume",#REF!,T$1-2020,FALSE)))/ VLOOKUP($H17&";Volume",#REF!,T$1-2019,FALSE) -> #REF! | U21: =(6*VLOOKUP($H17&";TauxRenouvellement",#REF!,U$1-2020,FALSE)*VLOOKUP($H17&";Volume",#REF!,U$1-2020,FALSE)+ T21*(VLOOKUP($H17&";Volume",#REF!,U$1-2019,FALSE)-VLOOKUP($H17&";TauxRenouvellement",#REF!,U$1-2020,FALSE)*VLOOKUP($H17&";Volume",#REF!,U$1-2020,FALSE)))/ VLOOKUP($H17&";Volume",#REF!,U$1-2019,FALSE) -> #REF! | V21: =(6*VLOOKUP($H17&";TauxRenouvellement",#REF!,V$1-2020,FALSE)*VLOOKUP($H17&";Volume",#REF!,V$1-2020,FALSE)+ U21*(VLOOKUP($H17&";Volume",#REF!,V$1-2019,FALSE)-VLOOKUP($H17&";TauxRenouvellement",#REF!,V$1-2020,FALSE)*VLOOKUP($H17&";Volume",#REF!,V$1-2020,FALSE)))/ VLOOKUP($H17&";Volume",#REF!,V$1-2019,FALSE) -> #REF! | W21: =(6*VLOOKUP($H17&";TauxRenouvellement",#REF!,W$1-2020,FALSE)*VLOOKUP($H17&";Volume",#REF!,W$1-2020,FALSE)+ V21*(VLOOKUP($H17&";Volume",#REF!,W$1-2019,FALSE)-VLOOKUP($H17&";TauxRenouvellement",#REF!,W$1-2020,FALSE)*VLOOKUP($H17&";Volume",#REF!,W$1-2020,FALSE)))/ VLOOKUP($H17&";Volume",#REF!,W$1-2019,FALSE) -> #REF! | X21: =(6*VLOOKUP($H17&";TauxRenouvellement",#REF!,X$1-2020,FALSE)*VLOOKUP($H17&";Volume",#REF!,X$1-2020,FALSE)+ W21*(VLOOKUP($H17&";Volume",#REF!,X$1-2019,FALSE)-VLOOKUP($H17&";TauxRenouvellement",#REF!,X$1-2020,FALSE)*VLOOKUP($H17&";Volume",#REF!,X$1-2020,FALSE)))/ VLOOKUP($H17&";Volume",#REF!,X$1-2019,FALSE) -> #REF! | Y21: =(6*VLOOKUP($H17&";TauxRenouvellement",#REF!,Y$1-2020,FALSE)*VLOOKUP($H17&";Volume",#REF!,Y$1-2020,FALSE)+ X21*(VLOOKUP($H17&";Volume",#REF!,Y$1-2019,FALSE)-VLOOKUP($H17&";TauxRenouvellement",#REF!,Y$1-2020,FALSE)*VLOOKUP($H17&";Volume",#REF!,Y$1-2020,FALSE)))/ VLOOKUP($H17&";Volume",#REF!,Y$1-2019,FALSE) -> #REF! | ... AP21: =(6*VLOOKUP($H17&";TauxRenouvellement",#REF!,AP$1-2020,FALSE)*VLOOKUP($H17&";Volume",#REF!,AP$1-2020,FALSE)+ AO21*(VLOOKUP($H17&";Volume",#REF!,AP$1-2019,FALSE)-VLOOKUP($H17&";TauxRenouvellement",#REF!,AP$1-2020,FALSE)*VLOOKUP($H17&";Volume",#REF!,AP$1-2020,FALSE)))/ VLOOKUP($H17&";Volume",#REF!,AP$1-2019,FALSE) -> #REF!
A22: Fret routier | B22: Catégorie 2 | C22: Vignette Crit'Air | E22: =_xlfn.CONCAT("FretRout",LEFT(B22,3),RIGHT(B22,1),"CritAir") -> FretRoutCat2CritAir | F22: radio | G22: 1 | I22: 2 | K22: =I22 -> 2 | Q22: #REF! | R22: =(VLOOKUP($H17&";TauxRenouvellement",#REF!,R$1-2020,FALSE)*VLOOKUP($H17&";Volume",#REF!,R$1-2020,FALSE)+ Q22*(VLOOKUP($H17&";Volume",#REF!,R$1-2019,FALSE)-VLOOKUP($H17&";TauxRenouvellement",#REF!,R$1-2020,FALSE)*VLOOKUP($H17&";Volume",#REF!,R$1-2020,FALSE)))/ VLOOKUP($H17&";Volume",#REF!,R$1-2019,FALSE) -> #REF! | S22: =(VLOOKUP($H17&";TauxRenouvellement",#REF!,S$1-2020,FALSE)*VLOOKUP($H17&";Volume",#REF!,S$1-2020,FALSE)+ R22*(VLOOKUP($H17&";Volume",#REF!,S$1-2019,FALSE)-VLOOKUP($H17&";TauxRenouvellement",#REF!,S$1-2020,FALSE)*VLOOKUP($H17&";Volume",#REF!,S$1-2020,FALSE)))/ VLOOKUP($H17&";Volume",#REF!,S$1-2019,FALSE) -> #REF! | T22: =(VLOOKUP($H17&";TauxRenouvellement",#REF!,T$1-2020,FALSE)*VLOOKUP($H17&";Volume",#REF!,T$1-2020,FALSE)+ S22*(VLOOKUP($H17&";Volume",#REF!,T$1-2019,FALSE)-VLOOKUP($H17&";TauxRenouvellement",#REF!,T$1-2020,FALSE)*VLOOKUP($H17&";Volume",#REF!,T$1-2020,FALSE)))/ VLOOKUP($H17&";Volume",#REF!,T$1-2019,FALSE) -> #REF! | U22: =(VLOOKUP($H17&";TauxRenouvellement",#REF!,U$1-2020,FALSE)*VLOOKUP($H17&";Volume",#REF!,U$1-2020,FALSE)+ T22*(VLOOKUP($H17&";Volume",#REF!,U$1-2019,FALSE)-VLOOKUP($H17&";TauxRenouvellement",#REF!,U$1-2020,FALSE)*VLOOKUP($H17&";Volume",#REF!,U$1-2020,FALSE)))/ VLOOKUP($H17&";Volume",#REF!,U$1-2019,FALSE) -> #REF! | V22: =(VLOOKUP($H17&";TauxRenouvellement",#REF!,V$1-2020,FALSE)*VLOOKUP($H17&";Volume",#REF!,V$1-2020,FALSE)+ U22*(VLOOKUP($H17&";Volume",#REF!,V$1-2019,FALSE)-VLOOKUP($H17&";TauxRenouvellement",#REF!,V$1-2020,FALSE)*VLOOKUP($H17&";Volume",#REF!,V$1-2020,FALSE)))/ VLOOKUP($H17&";Volume",#REF!,V$1-2019,FALSE) -> #REF! | W22: =(VLOOKUP($H17&";TauxRenouvellement",#REF!,W$1-2020,FALSE)*VLOOKUP($H17&";Volume",#REF!,W$1-2020,FALSE)+ V22*(VLOOKUP($H17&";Volume",#REF!,W$1-2019,FALSE)-VLOOKUP($H17&";TauxRenouvellement",#REF!,W$1-2020,FALSE)*VLOOKUP($H17&";Volume",#REF!,W$1-2020,FALSE)))/ VLOOKUP($H17&";Volume",#REF!,W$1-2019,FALSE) -> #REF! | X22: =(VLOOKUP($H17&";TauxRenouvellement",#REF!,X$1-2020,FALSE)*VLOOKUP($H17&";Volume",#REF!,X$1-2020,FALSE)+ W22*(VLOOKUP($H17&";Volume",#REF!,X$1-2019,FALSE)-VLOOKUP($H17&";TauxRenouvellement",#REF!,X$1-2020,FALSE)*VLOOKUP($H17&";Volume",#REF!,X$1-2020,FALSE)))/ VLOOKUP($H17&";Volume",#REF!,X$1-2019,FALSE) -> #REF! | Y22: =(VLOOKUP($H17&";TauxRenouvellement",#REF!,Y$1-2020,FALSE)*VLOOKUP($H17&";Volume",#REF!,Y$1-2020,FALSE)+ X22*(VLOOKUP($H17&";Volume",#REF!,Y$1-2019,FALSE)-VLOOKUP($H17&";TauxRenouvellement",#REF!,Y$1-2020,FALSE)*VLOOKUP($H17&";Volume",#REF!,Y$1-2020,FALSE)))/ VLOOKUP($H17&";Volume",#REF!,Y$1-2019,FALSE) -> #REF! | ... AP22: =(VLOOKUP($H17&";TauxRenouvellement",#REF!,AP$1-2020,FALSE)*VLOOKUP($H17&";Volume",#REF!,AP$1-2020,FALSE)+ AO22*(VLOOKUP($H17&";Volume",#REF!,AP$1-2019,FALSE)-VLOOKUP($H17&";TauxRenouvellement",#REF!,AP$1-2020,FALSE)*VLOOKUP($H17&";Volume",#REF!,AP$1-2020,FALSE)))/ VLOOKUP($H17&";Volume",#REF!,AP$1-2019,FALSE) -> #REF!
A23: Fret routier | B23: Catégorie 2 | C23: Nombre de véhicules correspondants | E23: =_xlfn.CONCAT("FretRout",LEFT(B23,3),RIGHT(B23,1),"Nb") -> FretRoutCat2Nb | F23: number | G23: 1 | J23: véhicules | K23: 0
A24: Fret routier | B24: Catégorie 2 | C24: Ordre de grandeur de la distance parcourue annuellement (ensemble des véhicules renseignés pour la catégorie) | E24: =_xlfn.CONCAT("FretRout",LEFT(B24,3),RIGHT(B24,1),"Dist") -> FretRoutCat2Dist | F24: number | G24: 1 | J24: km | K24: 17855
A25: Fret routier | B25: Catégorie 2 | C25: Estimation du taux de remplissage moyen de ces véhicules | E25: =_xlfn.CONCAT("FretRout",LEFT(B25,3),RIGHT(B25,1),"Rempl") -> FretRoutCat2Rempl | F25: number | G25: 1 | H25: 0.87 | J25: % | K25: 0
A26: Fret routier | B26: Catégorie 3 | C26: Nom de la catégorie de véhicules | E26: =_xlfn.CONCAT("FretRout",LEFT(B26,3),RIGHT(B26,1),"Nom") -> FretRoutCat3Nom | F26: text | G26: 1 | I26: VUL Diesel (Crit'Air 3) | K26: =I26 -> VUL Diesel (Crit'Air 3)
A27: Fret routier | B27: Catégorie 3 | C27: Type de véhicule | E27: =_xlfn.CONCAT("FretRout",LEFT(B27,3),RIGHT(B27,1),"Type") -> FretRoutCat3Type | F27: text | G27: 1 | I27: VUL | K27: =I27 -> VUL
A28: Fret routier | B28: Catégorie 3 | C28: PTAC | E28: =_xlfn.CONCAT("FretRout",LEFT(B28,3),RIGHT(B28,1),"PTAC") -> FretRoutCat3PTAC | F28: radio | G28: 1 | I28: <=3,5t | K28: =I28 -> <=3,5t
A29: Fret routier | B29: Catégorie 3 | C29: Motorisation | E29: =_xlfn.CONCAT("FretRout",LEFT(B29,3),RIGHT(B29,1),"Mot") -> FretRoutCat3Mot | F29: radio | G29: 1 | I29: Diesel | K29: =I29 -> Diesel
A30: Fret routier | B30: Catégorie 3 | C30: Carburant utilisé | E30: =_xlfn.CONCAT("FretRout",LEFT(B30,3),RIGHT(B30,1),"Carb") -> FretRoutCat3Carb | F30: radio | G30: 1 | I30: Gazole à la pompe | K30: =I30 -> Gazole à la pompe
A31: Fret routier | B31: Catégorie 3 | C31: Norme Euro | E31: =_xlfn.CONCAT("FretRout",LEFT(B31,3),RIGHT(B31,1),"Euro") -> FretRoutCat3Euro | F31: radio | G31: 1 | I31: 0 | K31: =I31 -> 0 | Q31: #REF! | R31: =(6*VLOOKUP($H27&";TauxRenouvellement",#REF!,R$1-2020,FALSE)*VLOOKUP($H27&";Volume",#REF!,R$1-2020,FALSE)+ Q31*(VLOOKUP($H27&";Volume",#REF!,R$1-2019,FALSE)-VLOOKUP($H27&";TauxRenouvellement",#REF!,R$1-2020,FALSE)*VLOOKUP($H27&";Volume",#REF!,R$1-2020,FALSE)))/ VLOOKUP($H27&";Volume",#REF!,R$1-2019,FALSE) -> #REF! | S31: =(6*VLOOKUP($H27&";TauxRenouvellement",#REF!,S$1-2020,FALSE)*VLOOKUP($H27&";Volume",#REF!,S$1-2020,FALSE)+ R31*(VLOOKUP($H27&";Volume",#REF!,S$1-2019,FALSE)-VLOOKUP($H27&";TauxRenouvellement",#REF!,S$1-2020,FALSE)*VLOOKUP($H27&";Volume",#REF!,S$1-2020,FALSE)))/ VLOOKUP($H27&";Volume",#REF!,S$1-2019,FALSE) -> #REF! | T31: =(6*VLOOKUP($H27&";TauxRenouvellement",#REF!,T$1-2020,FALSE)*VLOOKUP($H27&";Volume",#REF!,T$1-2020,FALSE)+ S31*(VLOOKUP($H27&";Volume",#REF!,T$1-2019,FALSE)-VLOOKUP($H27&";TauxRenouvellement",#REF!,T$1-2020,FALSE)*VLOOKUP($H27&";Volume",#REF!,T$1-2020,FALSE)))/ VLOOKUP($H27&";Volume",#REF!,T$1-2019,FALSE) -> #REF! | U31: =(6*VLOOKUP($H27&";TauxRenouvellement",#REF!,U$1-2020,FALSE)*VLOOKUP($H27&";Volume",#REF!,U$1-2020,FALSE)+ T31*(VLOOKUP($H27&";Volume",#REF!,U$1-2019,FALSE)-VLOOKUP($H27&";TauxRenouvellement",#REF!,U$1-2020,FALSE)*VLOOKUP($H27&";Volume",#REF!,U$1-2020,FALSE)))/ VLOOKUP($H27&";Volume",#REF!,U$1-2019,FALSE) -> #REF! | V31: =(6*VLOOKUP($H27&";TauxRenouvellement",#REF!,V$1-2020,FALSE)*VLOOKUP($H27&";Volume",#REF!,V$1-2020,FALSE)+ U31*(VLOOKUP($H27&";Volume",#REF!,V$1-2019,FALSE)-VLOOKUP($H27&";TauxRenouvellement",#REF!,V$1-2020,FALSE)*VLOOKUP($H27&";Volume",#REF!,V$1-2020,FALSE)))/ VLOOKUP($H27&";Volume",#REF!,V$1-2019,FALSE) -> #REF! | W31: =(6*VLOOKUP($H27&";TauxRenouvellement",#REF!,W$1-2020,FALSE)*VLOOKUP($H27&";Volume",#REF!,W$1-2020,FALSE)+ V31*(VLOOKUP($H27&";Volume",#REF!,W$1-2019,FALSE)-VLOOKUP($H27&";TauxRenouvellement",#REF!,W$1-2020,FALSE)*VLOOKUP($H27&";Volume",#REF!,W$1-2020,FALSE)))/ VLOOKUP($H27&";Volume",#REF!,W$1-2019,FALSE) -> #REF! | X31: =(6*VLOOKUP($H27&";TauxRenouvellement",#REF!,X$1-2020,FALSE)*VLOOKUP($H27&";Volume",#REF!,X$1-2020,FALSE)+ W31*(VLOOKUP($H27&";Volume",#REF!,X$1-2019,FALSE)-VLOOKUP($H27&";TauxRenouvellement",#REF!,X$1-2020,FALSE)*VLOOKUP($H27&";Volume",#REF!,X$1-2020,FALSE)))/ VLOOKUP($H27&";Volume",#REF!,X$1-2019,FALSE) -> #REF! | Y31: =(6*VLOOKUP($H27&";TauxRenouvellement",#REF!,Y$1-2020,FALSE)*VLOOKUP($H27&";Volume",#REF!,Y$1-2020,FALSE)+ X31*(VLOOKUP($H27&";Volume",#REF!,Y$1-2019,FALSE)-VLOOKUP($H27&";TauxRenouvellement",#REF!,Y$1-2020,FALSE)*VLOOKUP($H27&";Volume",#REF!,Y$1-2020,FALSE)))/ VLOOKUP($H27&";Volume",#REF!,Y$1-2019,FALSE) -> #REF! | ... AP31: =(6*VLOOKUP($H27&";TauxRenouvellement",#REF!,AP$1-2020,FALSE)*VLOOKUP($H27&";Volume",#REF!,AP$1-2020,FALSE)+ AO31*(VLOOKUP($H27&";Volume",#REF!,AP$1-2019,FALSE)-VLOOKUP($H27&";TauxRenouvellement",#REF!,AP$1-2020,FALSE)*VLOOKUP($H27&";Volume",#REF!,AP$1-2020,FALSE)))/ VLOOKUP($H27&";Volume",#REF!,AP$1-2019,FALSE) -> #REF!
A32: Fret routier | B32: Catégorie 3 | C32: Vignette Crit'Air | E32: =_xlfn.CONCAT("FretRout",LEFT(B32,3),RIGHT(B32,1),"CritAir") -> FretRoutCat3CritAir | F32: radio | G32: 1 | I32: 3 | K32: =I32 -> 3 | Q32: #REF! | R32: =(VLOOKUP($H27&";TauxRenouvellement",#REF!,R$1-2020,FALSE)*VLOOKUP($H27&";Volume",#REF!,R$1-2020,FALSE)+ Q32*(VLOOKUP($H27&";Volume",#REF!,R$1-2019,FALSE)-VLOOKUP($H27&";TauxRenouvellement",#REF!,R$1-2020,FALSE)*VLOOKUP($H27&";Volume",#REF!,R$1-2020,FALSE)))/ VLOOKUP($H27&";Volume",#REF!,R$1-2019,FALSE) -> #REF! | S32: =(VLOOKUP($H27&";TauxRenouvellement",#REF!,S$1-2020,FALSE)*VLOOKUP($H27&";Volume",#REF!,S$1-2020,FALSE)+ R32*(VLOOKUP($H27&";Volume",#REF!,S$1-2019,FALSE)-VLOOKUP($H27&";TauxRenouvellement",#REF!,S$1-2020,FALSE)*VLOOKUP($H27&";Volume",#REF!,S$1-2020,FALSE)))/ VLOOKUP($H27&";Volume",#REF!,S$1-2019,FALSE) -> #REF! | T32: =(VLOOKUP($H27&";TauxRenouvellement",#REF!,T$1-2020,FALSE)*VLOOKUP($H27&";Volume",#REF!,T$1-2020,FALSE)+ S32*(VLOOKUP($H27&";Volume",#REF!,T$1-2019,FALSE)-VLOOKUP($H27&";TauxRenouvellement",#REF!,T$1-2020,FALSE)*VLOOKUP($H27&";Volume",#REF!,T$1-2020,FALSE)))/ VLOOKUP($H27&";Volume",#REF!,T$1-2019,FALSE) -> #REF! | U32: =(VLOOKUP($H27&";TauxRenouvellement",#REF!,U$1-2020,FALSE)*VLOOKUP($H27&";Volume",#REF!,U$1-2020,FALSE)+ T32*(VLOOKUP($H27&";Volume",#REF!,U$1-2019,FALSE)-VLOOKUP($H27&";TauxRenouvellement",#REF!,U$1-2020,FALSE)*VLOOKUP($H27&";Volume",#REF!,U$1-2020,FALSE)))/ VLOOKUP($H27&";Volume",#REF!,U$1-2019,FALSE) -> #REF! | V32: =(VLOOKUP($H27&";TauxRenouvellement",#REF!,V$1-2020,FALSE)*VLOOKUP($H27&";Volume",#REF!,V$1-2020,FALSE)+ U32*(VLOOKUP($H27&";Volume",#REF!,V$1-2019,FALSE)-VLOOKUP($H27&";TauxRenouvellement",#REF!,V$1-2020,FALSE)*VLOOKUP($H27&";Volume",#REF!,V$1-2020,FALSE)))/ VLOOKUP($H27&";Volume",#REF!,V$1-2019,FALSE) -> #REF! | W32: =(VLOOKUP($H27&";TauxRenouvellement",#REF!,W$1-2020,FALSE)*VLOOKUP($H27&";Volume",#REF!,W$1-2020,FALSE)+ V32*(VLOOKUP($H27&";Volume",#REF!,W$1-2019,FALSE)-VLOOKUP($H27&";TauxRenouvellement",#REF!,W$1-2020,FALSE)*VLOOKUP($H27&";Volume",#REF!,W$1-2020,FALSE)))/ VLOOKUP($H27&";Volume",#REF!,W$1-2019,FALSE) -> #REF! | X32: =(VLOOKUP($H27&";TauxRenouvellement",#REF!,X$1-2020,FALSE)*VLOOKUP($H27&";Volume",#REF!,X$1-2020,FALSE)+ W32*(VLOOKUP($H27&";Volume",#REF!,X$1-2019,FALSE)-VLOOKUP($H27&";TauxRenouvellement",#REF!,X$1-2020,FALSE)*VLOOKUP($H27&";Volume",#REF!,X$1-2020,FALSE)))/ VLOOKUP($H27&";Volume",#REF!,X$1-2019,FALSE) -> #REF! | Y32: =(VLOOKUP($H27&";TauxRenouvellement",#REF!,Y$1-2020,FALSE)*VLOOKUP($H27&";Volume",#REF!,Y$1-2020,FALSE)+ X32*(VLOOKUP($H27&";Volume",#REF!,Y$1-2019,FALSE)-VLOOKUP($H27&";TauxRenouvellement",#REF!,Y$1-2020,FALSE)*VLOOKUP($H27&";Volume",#REF!,Y$1-2020,FALSE)))/ VLOOKUP($H27&";Volume",#REF!,Y$1-2019,FALSE) -> #REF! | ... AP32: =(VLOOKUP($H27&";TauxRenouvellement",#REF!,AP$1-2020,FALSE)*VLOOKUP($H27&";Volume",#REF!,AP$1-2020,FALSE)+ AO32*(VLOOKUP($H27&";Volume",#REF!,AP$1-2019,FALSE)-VLOOKUP($H27&";TauxRenouvellement",#REF!,AP$1-2020,FALSE)*VLOOKUP($H27&";Volume",#REF!,AP$1-2020,FALSE)))/ VLOOKUP($H27&";Volume",#REF!,AP$1-2019,FALSE) -> #REF!
A33: Fret routier | B33: Catégorie 3 | C33: Nombre de véhicules correspondants | E33: =_xlfn.CONCAT("FretRout",LEFT(B33,3),RIGHT(B33,1),"Nb") -> FretRoutCat3Nb | F33: number | G33: 1 | J33: véhicules | K33: 0
A34: Fret routier | B34: Catégorie 3 | C34: Ordre de grandeur de la distance parcourue annuellement (ensemble des véhicules renseignés pour la catégorie) | E34: =_xlfn.CONCAT("FretRout",LEFT(B34,3),RIGHT(B34,1),"Dist") -> FretRoutCat3Dist | F34: number | G34: 1 | J34: km | K34: 17855
A35: Fret routier | B35: Catégorie 3 | C35: Estimation du taux de remplissage moyen de ces véhicules | E35: =_xlfn.CONCAT("FretRout",LEFT(B35,3),RIGHT(B35,1),"Rempl") -> FretRoutCat3Rempl | F35: number | G35: 1 | J35: % | K35: 0
A36: Fret routier | B36: Catégorie 4 | C36: Nom de la catégorie de véhicules | E36: =_xlfn.CONCAT("FretRout",LEFT(B36,3),RIGHT(B36,1),"Nom") -> FretRoutCat4Nom | F36: text | G36: 1 | I36: VUL Diesel (Crit'Air 4) | K36: =I36 -> VUL Diesel (Crit'Air 4)
A37: Fret routier | B37: Catégorie 4 | C37: Type de véhicule | E37: =_xlfn.CONCAT("FretRout",LEFT(B37,3),RIGHT(B37,1),"Type") -> FretRoutCat4Type | F37: text | G37: 1 | I37: VUL | K37: =I37 -> VUL
A38: Fret routier | B38: Catégorie 4 | C38: PTAC | E38: =_xlfn.CONCAT("FretRout",LEFT(B38,3),RIGHT(B38,1),"PTAC") -> FretRoutCat4PTAC | F38: radio | G38: 1 | I38: <=3,5t | K38: =I38 -> <=3,5t
A39: Fret routier | B39: Catégorie 4 | C39: Motorisation | E39: =_xlfn.CONCAT("FretRout",LEFT(B39,3),RIGHT(B39,1),"Mot") -> FretRoutCat4Mot | F39: radio | G39: 1 | I39: Diesel | K39: =I39 -> Diesel
A40: Fret routier | B40: Catégorie 4 | C40: Carburant utilisé | E40: =_xlfn.CONCAT("FretRout",LEFT(B40,3),RIGHT(B40,1),"Carb") -> FretRoutCat4Carb | F40: radio | G40: 1 | I40: Gazole à la pompe | K40: =I40 -> Gazole à la pompe
...

Sheet Remplissage - Sit. Expost
A1: Catégorie | B1: Sous-catégorie | C1: Titre | D1: Description | E1: Nom de la variable | F1: Type | G1: Affichage | H1: Valeur | I1: Valeurs possibles | J1: Unité | K1: Valeur par défaut | L1: Commentaire | M1: Action(s) liée(s) | N1: Affichage à la création
A2: Données de base | C2: Année de remplissage des données | E2: AnneeRempl | F2: number | G2: 1 | H2: 2028 | N2: 1
A3: Données de base | C3: Nom du territoire | E3: NomTerr | F3: text | G3: 0 | H3: Nantes Métropole;Communauté de communes du Gâtinais en Bourgogne;Communauté de communes du Vexin-Val de Seine | K3: Nantes Métropole;Communauté de communes du Gâtinais en Bourgogne;Communauté de communes du Vexin-Val de Seine | N3: 1
A4: Données de base | C4: SIREN territoire | E4: SIRENTerr | F4: number | G4: 0 | H4: 999999999
A5: Données de base | C5: Nombre d'habitants | E5: NbHabTerr | F5: number | G5: 1 | J5: hab | K5: #REF!
A6: Données de base | C6: Nombre de ménages | E6: NbMenTerr | F6: number | G6: 1 | J6: ménages | K6: #REF!
A7: Données de base | C7: Superficie | E7: SupTerr | F7: number | G7: 1 | J7: km² | K7: #REF!
A8: Données de base | C8: Typologie de territoire | E8: TypoTerr | F8: radio | G8: 0 | I8: Territoire polarisé autour d'une commune centre,Territoire polarisé autour de plusieurs communes
A9: Données de base | C9: Nombre de communes "pôles" | E9: NbPolesTerr | F9: number | G9: =IF(H8="Territoire polarisé autour de plusieurs communes",1,0) -> 0 | H9: 0 | J9: pôles
A10: Données de base | C10: Nombre d'habitants dans la commune pôle n°1 | E10: NbHabPole1 | F10: number | G10: 1 | J10: hab
A11: Données de base | C11: Nombre d'habitants dans la commune pôle n°2 | E11: NbHabPole2 | F11: number | G11: =IF($H$9>1,1,0) -> 0 | J11: hab
A12: Données de base | C12: Nombre d'habitants dans la commune pôle n°3 | E12: NbHabPole3 | F12: number | G12: =IF($H$9>2,1,0) -> 0 | J12: hab
A13: Données de base | C13: Nombre d'habitants dans la commune pôle n°4 | E13: NbHabPole4 | F13: number | G13: =IF($H$9>3,1,0) -> 0 | J13: hab
A14: Données de base | C14: Nombre d'habitants dans la commune pôle n°5 | E14: NbHabPole5 | F14: number | G14: =IF($H$9>4,1,0) -> 0 | J14: hab
A15: Données de base | C15: Possibilité et intention de développement du fret fluvial ? | E15: FretFluv | F15: radio | G15: 0 | H15: Oui | I15: Oui,Non
A16: Données de base | C16: Possibilité et intention de développement du fret ferroviaire ? | E16: FretFerr | F16: radio | G16: 0 | H16: Oui | I16: Oui,Non
A17: Données de base | C17: Sélectionnez les actions du catalogue d'actions InTerLUD+ se rapprochant d'actions dont la mise en œuvre avait commencé en amont de l'engagement de votre territoire dans la démarche InTerLUD+ | E17: ActionsAutres | F17: checkbox | G17: 0 | H17: A1,A2,A3,B1,B3,B4,B5,C1,C2,C3,C4,C5,C6,C7,C8,C9 | I17: A1,A2,A3,B1,B2,B3,B4,B5,C1,C2,C3,C4,C5,C6,C7,C8,C9 | N17: 1
A18: Données de base | C18: Sélectionnez les actions du catalogue d'actions InTerLUD+ se rapprochant d'actions inscrites dans votre charte | E18: ActionsCharte | F18: checkbox | G18: 0 | H18: A1,A2,A3,B1,B3,B4,B5,C1,C2,C3,C4,C5,C6,C7,C8,C9 | I18: A1,A2,A3,B1,B2,B3,B4,B5,C1,C2,C3,C4,C5,C6,C7,C8,C9 | N18: 1
A19: Données de production/consommation d'énergie | C19: Y-a-t-il une ou plusieurs stations d'avitaillement GNV sur votre territoire ? | E19: GNV | F19: radio | G19: 1 | H19: Oui | I19: Oui,Non
A20: Données de production/consommation d'énergie | C20: Quelle est la part de bioGNV dans le GNV distribué dans cette ou ces stations d'avitaillement ? | E20: bioGNV | F20: number | G20: =IF(H19="Oui",1,0) -> 1 | H20: 1 | J20: %
A21: Données de production/consommation d'énergie | C21: Y-a-t-il une ou plusieurs stations d'avitaillement hydrogène sur votre territoire ? | E21: H2 | F21: radio | G21: 1 | H21: Oui | I21: Oui,Non
A22: Données de production/consommation d'énergie | C22: Origine de l'hydrogène utilisé | E22: H2Vert | F22: number | G22: =IF(H21="Oui",1,0) -> 1 | H22: Hydrogène produit à partir d'électricité renouvelable | I22: Hydrogène produit à partir d'électricité renouvelable,Hydrogène produit à partir de biométhane,Hydrogène produit à partir de ressources fossiles
A23: Fret routier | B23: Catégorie 1 | C23: Nom de la catégorie de véhicules | E23: =_xlfn.CONCAT("FretRout",LEFT(B23,3),RIGHT(B23,1),"Nom") -> FretRoutCat1Nom | F23: text | G23: 1 | I23: VUL Electrique (Crit'Air E) | K23: =I23 -> VUL Electrique (Crit'Air E)
A24: Fret routier | B24: Catégorie 1 | C24: Type de véhicule | E24: =_xlfn.CONCAT("FretRout",LEFT(B24,3),RIGHT(B24,1),"Type") -> FretRoutCat1Type | F24: text | G24: 1 | I24: VUL | K24: =I24 -> VUL
A25: Fret routier | B25: Catégorie 1 | C25: PTAC | E25: =_xlfn.CONCAT("FretRout",LEFT(B25,3),RIGHT(B25,1),"PTAC") -> FretRoutCat1PTAC | F25: radio | G25: 1 | I25: <=3,5t | K25: =I25 -> <=3,5t
A26: Fret routier | B26: Catégorie 1 | C26: Motorisation | E26: =_xlfn.CONCAT("FretRout",LEFT(B26,3),RIGHT(B26,1),"Mot") -> FretRoutCat1Mot | F26: radio | G26: 1 | I26: Electrique | K26: =I26 -> Electrique
A27: Fret routier | B27: Catégorie 1 | C27: Carburant utilisé | E27: =_xlfn.CONCAT("FretRout",LEFT(B27,3),RIGHT(B27,1),"Carb") -> FretRoutCat1Carb | F27: radio | G27: 1 | I27: - | K27: =I27 -> -
A28: Fret routier | B28: Catégorie 1 | C28: Norme Euro | E28: =_xlfn.CONCAT("FretRout",LEFT(B28,3),RIGHT(B28,1),"Euro") -> FretRoutCat1Euro | F28: radio | G28: 1 | I28: 0 | K28: =I28 -> 0
A29: Fret routier | B29: Catégorie 1 | C29: Vignette Crit'Air | E29: =_xlfn.CONCAT("FretRout",LEFT(B29,3),RIGHT(B29,1),"CritAir") -> FretRoutCat1CritAir | F29: radio | G29: 1 | I29: E | K29: =I29 -> E
A30: Fret routier | B30: Catégorie 1 | C30: Nombre de véhicules correspondants | E30: =_xlfn.CONCAT("FretRout",LEFT(B30,3),RIGHT(B30,1),"Nb") -> FretRoutCat1Nb | F30: number | G30: 1 | J30: véhicules | K30: 0
A31: Fret routier | B31: Catégorie 1 | C31: Ordre de grandeur de la distance parcourue annuellement (ensemble des véhicules renseignés pour la catégorie) | E31: =_xlfn.CONCAT("FretRout",LEFT(B31,3),RIGHT(B31,1),"Dist") -> FretRoutCat1Dist | F31: number | G31: 1 | J31: km | K31: 7694
A32: Fret routier | B32: Catégorie 1 | C32: Estimation du taux de remplissage moyen de ces véhicules | E32: =_xlfn.CONCAT("FretRout",LEFT(B32,3),RIGHT(B32,1),"Rempl") -> FretRoutCat1Rempl | F32: number | G32: 1 | J32: % | K32: 0
A33: Fret routier | B33: Catégorie 2 | C33: Nom de la catégorie de véhicules | E33: =_xlfn.CONCAT("FretRout",LEFT(B33,3),RIGHT(B33,1),"Nom") -> FretRoutCat2Nom | F33: text | G33: 1 | I33: VUL Diesel (Crit'Air 2) | K33: =I33 -> VUL Diesel (Crit'Air 2)
A34: Fret routier | B34: Catégorie 2 | C34: Type de véhicule | E34: =_xlfn.CONCAT("FretRout",LEFT(B34,3),RIGHT(B34,1),"Type") -> FretRoutCat2Type | F34: text | G34: 1 | I34: VUL | K34: =I34 -> VUL
A35: Fret routier | B35: Catégorie 2 | C35: PTAC | E35: =_xlfn.CONCAT("FretRout",LEFT(B35,3),RIGHT(B35,1),"PTAC") -> FretRoutCat2PTAC | F35: radio | G35: 1 | I35: <=3,5t | K35: =I35 -> <=3,5t
A36: Fret routier | B36: Catégorie 2 | C36: Motorisation | E36: =_xlfn.CONCAT("FretRout",LEFT(B36,3),RIGHT(B36,1),"Mot") -> FretRoutCat2Mot | F36: radio | G36: 1 | I36: Diesel | K36: =I36 -> Diesel
A37: Fret routier | B37: Catégorie 2 | C37: Carburant utilisé | E37: =_xlfn.CONCAT("FretRout",LEFT(B37,3),RIGHT(B37,1),"Carb") -> FretRoutCat2Carb | F37: radio | G37: 1 | I37: Gazole à la pompe | K37: =I37 -> Gazole à la pompe
A38: Fret routier | B38: Catégorie 2 | C38: Norme Euro | E38: =_xlfn.CONCAT("FretRout",LEFT(B38,3),RIGHT(B38,1),"Euro") -> FretRoutCat2Euro | F38: radio | G38: 1 | I38: 0 | K38: =I38 -> 0
A39: Fret routier | B39: Catégorie 2 | C39: Vignette Crit'Air | E39: =_xlfn.CONCAT("FretRout",LEFT(B39,3),RIGHT(B39,1),"CritAir") -> FretRoutCat2CritAir | F39: radio | G39: 1 | I39: 2 | K39: =I39 -> 2
A40: Fret routier | B40: Catégorie 2 | C40: Nombre de véhicules correspondants | E40: =_xlfn.CONCAT("FretRout",LEFT(B40,3),RIGHT(B40,1),"Nb") -> FretRoutCat2Nb | F40: number | G40: 1 | J40: véhicules | K40: 0
...

Sheet Remplissage - Sit. Prev.
A1: Catégorie | B1: Sous-catégorie | C1: Titre | D1: Description | E1: Nom de la variable | F1: Type | G1: Affichage | H1: Valeur | I1: Valeurs possibles | J1: Unité | K1: Valeur par défaut | L1: Commentaire | M1: Action(s) liée(s) | N1: Affichage à la création | O1: Ligne
A2: Données de base | C2: Année correspondant aux objectifs | E2: AnneeRempl | F2: number | G2: 1 | N2: 1 | O2: =ROW(O2)-1 -> 1
A3: Généralités | C3: Projection de population | E3: ProjPop | F3: number | G3: 0 | J3: hab
A4: Généralités | C4: Projection de nombre de ménages | E4: ProjMen | F4: number | G4: 0 | J4: ménages
A5: Généralités | C5: Prévision d'évolution de la demande de logistique urbaine | E5: DemandeLU | F5: number | G5: 1 | J5: % | O5: =ROW(O5)-1 -> 4
A6: Généralités | B6: Objectif de part modale pour les déplacements locaux | C6: Marche | E6: ObjPMMarche | F6: number | G6: 1 | J6: % | O6: =ROW(O6)-1 -> 5
A7: Généralités | B7: Objectif de part modale pour les déplacements locaux | C7: Vélo | E7: ObjPMVélo | F7: number | G7: 1 | J7: % | O7: =ROW(O7)-1 -> 6
A8: Généralités | B8: Objectif de part modale pour les déplacements locaux | C8: Deux-roues motorisé | E8: ObjPM2RM | F8: radio | G8: 1 | J8: % | O8: =ROW(O8)-1 -> 7
A9: Généralités | B9: Objectif de part modale pour les déplacements locaux | C9: Voiture | E9: ObjPMVoiture | F9: number | G9: 1 | J9: % | O9: =ROW(O9)-1 -> 8
A10: Généralités | B10: Objectif de part modale pour les déplacements locaux | C10: Transport en commun | E10: ObjPMTC | F10: number | G10: 1 | J10: % | O10: =ROW(O10)-1 -> 9
A11: Généralités | B11: Objectif de part modale pour le transport de marchandises | C11: Fret routier | E11: ObjPMRoutier | F11: number | G11: 1 | J11: % | O11: =ROW(O11)-1 -> 10
A12: Généralités | B12: Objectif de part modale pour le transport de marchandises | C12: Fret ferroviaire | E12: ObjPMFerroviaire | F12: number | G12: 1 | J12: % | O12: =ROW(O12)-1 -> 11
A13: Généralités | B13: Objectif de part modale pour le transport de marchandises | C13: Fret fluvial | E13: ObjPMFluvial | F13: number | G13: 1 | J13: % | O13: =ROW(O13)-1 -> 12
A14: Généralités | B14: Objectif de part modale pour le transport de marchandises | C14: Cyclologistique | E14: ObjPMCyclolog | F14: number | G14: 1 | J14: % | O14: =ROW(O14)-1 -> 13
A15: Généralités | C15: Objectif de part de bioGNV dans le GNV distribué dans la ou les stations d'avitaillement GNV du territoire | E15: ObjbioGNV | F15: number | G15: 1 | J15: % | O15: =ROW(O15)-1 -> 14
A16: Généralités | C16: Objectif de typologie d'hydrogène utilisé dans la ou les stations d'avitaillement hydrogène du territoire | E16: ObjH2Vert | F16: radio | G16: 1 | I16: Hydrogène produit à partir d'électricité renouvelable,Hydrogène produit à partir de biométhane,Hydrogène produit à partir de ressources fossiles | O16: =ROW(O16)-1 -> 15
A17: Evolution du parc routier initial | B17: Evolution 1 | C17: =_xlfn.CONCAT("Evolution visée pour les ",INDIRECT("'Parcs types'!D"&D17)) -> Evolution visée pour les Nom | D17: 7 | E17: =_xlfn.CONCAT(LEFT(B17,3),RIGHT(B17,1),"Vis") -> Evo1Vis | F17: number | G17: {=IF((INDEX('Remplissage - Sit. Init.'!$C$23:$I$472,MATCH((_xlfn.CONCAT("Catégorie "&RIGHT(B17,1)))&('Remplissage - Sit. Init.'!$D$30),('Remplissage - Sit. Init.'!$C$23:$C$472)&('Remplissage - Sit. Init.'!$D$23:$D$472),0),7))>0,1,0)} -> 0 | J17: % | L17: La valeur à indiquer ici, est le pourcentage d'augmentation de la catégorie de véhicule (nombre de véhicule et nombre de kilomètre)
A18: Evolution du parc routier initial | B18: Evolution du TR 1 | C18: =_xlfn.CONCAT("Evolution visée du taux de remplissage pour les ",INDIRECT("'Parcs types'!D"&D18)) -> Evolution visée du taux de remplissage pour les Nom | D18: 7 | E18: =_xlfn.CONCAT(LEFT(B18,3),RIGHT(B18,1),"VisTR") -> Evo1VisTR | F18: number | G18: {=IF((INDEX('Remplissage - Sit. Init.'!$C$23:$I$472,MATCH((_xlfn.CONCAT("Catégorie "&RIGHT(B18,1)))&('Remplissage - Sit. Init.'!$D$32),('Remplissage - Sit. Init.'!$C$23:$C$472)&('Remplissage - Sit. Init.'!$D$23:$D$472),0),7))>0,1,0)} -> 0 | J18: % | L18: La valeur à indiquer ici, est le pourcentage d'augmentation du taux de remplissage de la catégorie de véhicule
A19: Evolution du parc routier initial | B19: Evolution 2 | C19: =_xlfn.CONCAT("Evolution visée pour les ",INDIRECT("'Parcs types'!D"&D19)) -> Evolution visée pour les - | D19: 8 | E19: =_xlfn.CONCAT(LEFT(B19,3),RIGHT(B19,1),"Vis") -> Evo2Vis | F19: number | G19: {=IF((INDEX('Remplissage - Sit. Init.'!$C$23:$I$472,MATCH((_xlfn.CONCAT("Catégorie "&RIGHT(B19,1)))&('Remplissage - Sit. Init.'!$D$30),('Remplissage - Sit. Init.'!$C$23:$C$472)&('Remplissage - Sit. Init.'!$D$23:$D$472),0),7))>0,1,0)} -> 0 | J19: % | L19: La valeur à indiquer ici, est le pourcentage d'augmentation de la catégorie de véhicule (nombre de véhicule et nombre de kilomètre)
A20: Evolution du parc routier initial | B20: Evolution du TR 2 | C20: =_xlfn.CONCAT("Evolution visée du taux de remplissage pour les ",INDIRECT("'Parcs types'!D"&D20)) -> Evolution visée du taux de remplissage pour les - | D20: 8 | E20: =_xlfn.CONCAT(LEFT(B20,3),RIGHT(B20,1),"VisTR") -> Evo2VisTR | F20: number | G20: {=IF((INDEX('Remplissage - Sit. Init.'!$C$23:$I$472,MATCH((_xlfn.CONCAT("Catégorie "&RIGHT(B20,1)))&('Remplissage - Sit. Init.'!$D$32),('Remplissage - Sit. Init.'!$C$23:$C$472)&('Remplissage - Sit. Init.'!$D$23:$D$472),0),7))>0,1,0)} -> 0 | J20: % | L20: La valeur à indiquer ici, est le pourcentage d'augmentation du taux de remplissage de la catégorie de véhicule
A21: Evolution du parc routier initial | B21: Evolution 3 | C21: =_xlfn.CONCAT("Evolution visée pour les ",INDIRECT("'Parcs types'!D"&D21)) -> Evolution visée pour les Défaut | D21: 9 | E21: =_xlfn.CONCAT(LEFT(B21,3),RIGHT(B21,1),"Vis") -> Evo3Vis | F21: number | G21: {=IF((INDEX('Remplissage - Sit. Init.'!$C$23:$I$472,MATCH((_xlfn.CONCAT("Catégorie "&RIGHT(B21,1)))&('Remplissage - Sit. Init.'!$D$30),('Remplissage - Sit. Init.'!$C$23:$C$472)&('Remplissage - Sit. Init.'!$D$23:$D$472),0),7))>0,1,0)} -> 0 | J21: % | L21: La valeur à indiquer ici, est le pourcentage d'augmentation de la catégorie de véhicule (nombre de véhicule et nombre de kilomètre)
A22: Evolution du parc routier initial | B22: Evolution du TR 3 | C22: =_xlfn.CONCAT("Evolution visée du taux de remplissage pour les ",INDIRECT("'Parcs types'!D"&D22)) -> Evolution visée du taux de remplissage pour les Défaut | D22: 9 | E22: =_xlfn.CONCAT(LEFT(B22,3),RIGHT(B22,1),"VisTR") -> Evo3VisTR | F22: number | G22: {=IF((INDEX('Remplissage - Sit. Init.'!$C$23:$I$472,MATCH((_xlfn.CONCAT("Catégorie "&RIGHT(B22,1)))&('Remplissage - Sit. Init.'!$D$32),('Remplissage - Sit. Init.'!$C$23:$C$472)&('Remplissage - Sit. Init.'!$D$23:$D$472),0),7))>0,1,0)} -> 0 | J22: % | L22: La valeur à indiquer ici, est le pourcentage d'augmentation du taux de remplissage de la catégorie de véhicule
A23: Evolution du parc routier initial | B23: Evolution 4 | C23: =_xlfn.CONCAT("Evolution visée pour les ",INDIRECT("'Parcs types'!D"&D23)) -> Evolution visée pour les VUL Electrique (Crit'Air E) | D23: 10 | E23: =_xlfn.CONCAT(LEFT(B23,3),RIGHT(B23,1),"Vis") -> Evo4Vis | F23: number | G23: {=IF((INDEX('Remplissage - Sit. Init.'!$C$23:$I$472,MATCH((_xlfn.CONCAT("Catégorie "&RIGHT(B23,1)))&('Remplissage - Sit. Init.'!$D$30),('Remplissage - Sit. Init.'!$C$23:$C$472)&('Remplissage - Sit. Init.'!$D$23:$D$472),0),7))>0,1,0)} -> 0 | J23: % | L23: La valeur à indiquer ici, est le pourcentage d'augmentation de la catégorie de véhicule (nombre de véhicule et nombre de kilomètre)
A24: Evolution du parc routier initial | B24: Evolution du TR 4 | C24: =_xlfn.CONCAT("Evolution visée du taux de remplissage pour les ",INDIRECT("'Parcs types'!D"&D24)) -> Evolution visée du taux de remplissage pour les VUL Electrique (Crit'Air E) | D24: 10 | E24: =_xlfn.CONCAT(LEFT(B24,3),RIGHT(B24,1),"VisTR") -> Evo4VisTR | F24: number | G24: {=IF((INDEX('Remplissage - Sit. Init.'!$C$23:$I$472,MATCH((_xlfn.CONCAT("Catégorie "&RIGHT(B24,1)))&('Remplissage - Sit. Init.'!$D$32),('Remplissage - Sit. Init.'!$C$23:$C$472)&('Remplissage - Sit. Init.'!$D$23:$D$472),0),7))>0,1,0)} -> 0 | J24: % | L24: La valeur à indiquer ici, est le pourcentage d'augmentation du taux de remplissage de la catégorie de véhicule
A25: Evolution du parc routier initial | B25: Evolution 5 | C25: =_xlfn.CONCAT("Evolution visée pour les ",INDIRECT("'Parcs types'!D"&D25)) -> Evolution visée pour les VUL Diesel (Crit'Air 2) | D25: 11 | E25: =_xlfn.CONCAT(LEFT(B25,3),RIGHT(B25,1),"Vis") -> Evo5Vis | F25: number | G25: {=IF((INDEX('Remplissage - Sit. Init.'!$C$23:$I$472,MATCH((_xlfn.CONCAT("Catégorie "&RIGHT(B25,1)))&('Remplissage - Sit. Init.'!$D$30),('Remplissage - Sit. Init.'!$C$23:$C$472)&('Remplissage - Sit. Init.'!$D$23:$D$472),0),7))>0,1,0)} -> 0 | J25: % | L25: La valeur à indiquer ici, est le pourcentage d'augmentation de la catégorie de véhicule (nombre de véhicule et nombre de kilomètre)
A26: Evolution du parc routier initial | B26: Evolution du TR 5 | C26: =_xlfn.CONCAT("Evolution visée du taux de remplissage pour les ",INDIRECT("'Parcs types'!D"&D26)) -> Evolution visée du taux de remplissage pour les VUL Diesel (Crit'Air 2) | D26: 11 | E26: =_xlfn.CONCAT(LEFT(B26,3),RIGHT(B26,1),"VisTR") -> Evo5VisTR | F26: number | G26: {=IF((INDEX('Remplissage - Sit. Init.'!$C$23:$I$472,MATCH((_xlfn.CONCAT("Catégorie "&RIGHT(B26,1)))&('Remplissage - Sit. Init.'!$D$32),('Remplissage - Sit. Init.'!$C$23:$C$472)&('Remplissage - Sit. Init.'!$D$23:$D$472),0),7))>0,1,0)} -> 0 | J26: % | L26: La valeur à indiquer ici, est le pourcentage d'augmentation du taux de remplissage de la catégorie de véhicule
A27: Evolution du parc routier initial | B27: Evolution 6 | C27: =_xlfn.CONCAT("Evolution visée pour les ",INDIRECT("'Parcs types'!D"&D27)) -> Evolution visée pour les VUL Diesel (Crit'Air 3) | D27: 12 | E27: =_xlfn.CONCAT(LEFT(B27,3),RIGHT(B27,1),"Vis") -> Evo6Vis | F27: number | G27: {=IF((INDEX('Remplissage - Sit. Init.'!$C$23:$I$472,MATCH((_xlfn.CONCAT("Catégorie "&RIGHT(B27,1)))&('Remplissage - Sit. Init.'!$D$30),('Remplissage - Sit. Init.'!$C$23:$C$472)&('Remplissage - Sit. Init.'!$D$23:$D$472),0),7))>0,1,0)} -> 0 | J27: % | L27: La valeur à indiquer ici, est le pourcentage d'augmentation de la catégorie de véhicule (nombre de véhicule et nombre de kilomètre)
A28: Evolution du parc routier initial | B28: Evolution du TR 6 | C28: =_xlfn.CONCAT("Evolution visée du taux de remplissage pour les ",INDIRECT("'Parcs types'!D"&D28)) -> Evolution visée du taux de remplissage pour les VUL Diesel (Crit'Air 3) | D28: 12 | E28: =_xlfn.CONCAT(LEFT(B28,3),RIGHT(B28,1),"VisTR") -> Evo6VisTR | F28: number | G28: {=IF((INDEX('Remplissage - Sit. Init.'!$C$23:$I$472,MATCH((_xlfn.CONCAT("Catégorie "&RIGHT(B28,1)))&('Remplissage - Sit. Init.'!$D$32),('Remplissage - Sit. Init.'!$C$23:$C$472)&('Remplissage - Sit. Init.'!$D$23:$D$472),0),7))>0,1,0)} -> 0 | J28: % | L28: La valeur à indiquer ici, est le pourcentage d'augmentation du taux de remplissage de la catégorie de véhicule
A29: Evolution du parc routier initial | B29: Evolution 7 | C29: =_xlfn.CONCAT("Evolution visée pour les ",INDIRECT("'Parcs types'!D"&D29)) -> Evolution visée pour les VUL Diesel (Crit'Air 4) | D29: 13 | E29: =_xlfn.CONCAT(LEFT(B29,3),RIGHT(B29,1),"Vis") -> Evo7Vis | F29: number | G29: {=IF((INDEX('Remplissage - Sit. Init.'!$C$23:$I$472,MATCH((_xlfn.CONCAT("Catégorie "&RIGHT(B29,1)))&('Remplissage - Sit. Init.'!$D$30),('Remplissage - Sit. Init.'!$C$23:$C$472)&('Remplissage - Sit. Init.'!$D$23:$D$472),0),7))>0,1,0)} -> 0 | J29: % | L29: La valeur à indiquer ici, est le pourcentage d'augmentation de la catégorie de véhicule (nombre de véhicule et nombre de kilomètre)
A30: Evolution du parc routier initial | B30: Evolution du TR 7 | C30: =_xlfn.CONCAT("Evolution visée du taux de remplissage pour les ",INDIRECT("'Parcs types'!D"&D30)) -> Evolution visée du taux de remplissage pour les VUL Diesel (Crit'Air 4) | D30: 13 | E30: =_xlfn.CONCAT(LEFT(B30,3),RIGHT(B30,1),"VisTR") -> Evo7VisTR | F30: number | G30: {=IF((INDEX('Remplissage - Sit. Init.'!$C$23:$I$472,MATCH((_xlfn.CONCAT("Catégorie "&RIGHT(B30,1)))&('Remplissage - Sit. Init.'!$D$32),('Remplissage - Sit. Init.'!$C$23:$C$472)&('Remplissage - Sit. Init.'!$D$23:$D$472),0),7))>0,1,0)} -> 0 | J30: % | L30: La valeur à indiquer ici, est le pourcentage d'augmentation du taux de remplissage de la catégorie de véhicule
A31: Evolution du parc routier initial | B31: Evolution 8 | C31: =_xlfn.CONCAT("Evolution visée pour les ",INDIRECT("'Parcs types'!D"&D31)) -> Evolution visée pour les VUL Diesel (Crit'Air 5) | D31: 14 | E31: =_xlfn.CONCAT(LEFT(B31,3),RIGHT(B31,1),"Vis") -> Evo8Vis | F31: number | G31: {=IF((INDEX('Remplissage - Sit. Init.'!$C$23:$I$472,MATCH((_xlfn.CONCAT("Catégorie "&RIGHT(B31,1)))&('Remplissage - Sit. Init.'!$D$30),('Remplissage - Sit. Init.'!$C$23:$C$472)&('Remplissage - Sit. Init.'!$D$23:$D$472),0),7))>0,1,0)} -> 0 | J31: % | L31: La valeur à indiquer ici, est le pourcentage d'augmentation de la catégorie de véhicule (nombre de véhicule et nombre de kilomètre)
A32: Evolution du parc routier initial | B32: Evolution du TR 8 | C32: =_xlfn.CONCAT("Evolution visée du taux de remplissage pour les ",INDIRECT("'Parcs types'!D"&D32)) -> Evolution visée du taux de remplissage pour les VUL Diesel (Crit'Air 5) | D32: 14 | E32: =_xlfn.CONCAT(LEFT(B32,3),RIGHT(B32,1),"VisTR") -> Evo8VisTR | F32: number | G32: {=IF((INDEX('Remplissage - Sit. Init.'!$C$23:$I$472,MATCH((_xlfn.CONCAT("Catégorie "&RIGHT(B32,1)))&('Remplissage - Sit. Init.'!$D$32),('Remplissage - Sit. Init.'!$C$23:$C$472)&('Remplissage - Sit. Init.'!$D$23:$D$472),0),7))>0,1,0)} -> 0 | J32: % | L32: La valeur à indiquer ici, est le pourcentage d'augmentation du taux de remplissage de la catégorie de véhicule
A33: Evolution du parc routier initial | B33: Evolution 9 | C33: =_xlfn.CONCAT("Evolution visée pour les ",INDIRECT("'Parcs types'!D"&D33)) -> Evolution visée pour les VUL Essence (Crit'Air 1) | D33: 15 | E33: =_xlfn.CONCAT(LEFT(B33,3),RIGHT(B33,1),"Vis") -> Evo9Vis | F33: number | G33: {=IF((INDEX('Remplissage - Sit. Init.'!$C$23:$I$472,MATCH((_xlfn.CONCAT("Catégorie "&RIGHT(B33,1)))&('Remplissage - Sit. Init.'!$D$30),('Remplissage - Sit. Init.'!$C$23:$C$472)&('Remplissage - Sit. Init.'!$D$23:$D$472),0),7))>0,1,0)} -> 0 | J33: % | L33: La valeur à indiquer ici, est le pourcentage d'augmentation de la catégorie de véhicule (nombre de véhicule et nombre de kilomètre)
A34: Evolution du parc routier initial | B34: Evolution du TR 9 | C34: =_xlfn.CONCAT("Evolution visée du taux de remplissage pour les ",INDIRECT("'Parcs types'!D"&D34)) -> Evolution visée du taux de remplissage pour les VUL Essence (Crit'Air 1) | D34: 15 | E34: =_xlfn.CONCAT(LEFT(B34,3),RIGHT(B34,1),"VisTR") -> Evo9VisTR | F34: number | G34: {=IF((INDEX('Remplissage - Sit. Init.'!$C$23:$I$472,MATCH((_xlfn.CONCAT("Catégorie "&RIGHT(B34,1)))&('Remplissage - Sit. Init.'!$D$32),('Remplissage - Sit. Init.'!$C$23:$C$472)&('Remplissage - Sit. Init.'!$D$23:$D$472),0),7))>0,1,0)} -> 0 | J34: % | L34: La valeur à indiquer ici, est le pourcentage d'augmentation du taux de remplissage de la catégorie de véhicule
A35: Evolution du parc routier initial | B35: Evolution 10 | C35: =_xlfn.CONCAT("Evolution visée pour les ",INDIRECT("'Parcs types'!D"&D35)) -> Evolution visée pour les VUL Essence <=3,5t (Crit'Air 2) | D35: 16 | E35: =_xlfn.CONCAT(LEFT(B35,3),RIGHT(B35,2),"Vis") -> Evo10Vis | F35: number | G35: {=IF((INDEX('Remplissage - Sit. Init.'!$C$23:$I$472,MATCH((_xlfn.CONCAT("Catégorie "&RIGHT(B35,2)))&('Remplissage - Sit. Init.'!$D$30),('Remplissage - Sit. Init.'!$C$23:$C$472)&('Remplissage - Sit. Init.'!$D$23:$D$472),0),7))>0,1,0)} -> 0 | J35: % | L35: La valeur à indiquer ici, est le pourcentage d'augmentation de la catégorie de véhicule (nombre de véhicule et nombre de kilomètre)
A36: Evolution du parc routier initial | B36: Evolution du TR 10 | C36: =_xlfn.CONCAT("Evolution visée du taux de remplissage pour les ",INDIRECT("'Parcs types'!D"&D36)) -> Evolution visée du taux de remplissage pour les VUL Essence <=3,5t (Crit'Air 2) | D36: 16 | E36: =_xlfn.CONCAT(LEFT(B36,3),RIGHT(B36,2),"VisTR") -> Evo10VisTR | F36: number | G36: {=IF((INDEX('Remplissage - Sit. Init.'!$C$23:$I$472,MATCH((_xlfn.CONCAT("Catégorie "&RIGHT(B36,2)))&('Remplissage - Sit. Init.'!$D$32),('Remplissage - Sit. Init.'!$C$23:$C$472)&('Remplissage - Sit. Init.'!$D$23:$D$472),0),7))>0,1,0)} -> 0 | J36: % | L36: La valeur à indiquer ici, est le pourcentage d'augmentation du taux de remplissage de la catégorie de véhicule
A37: Evolution du parc routier initial | B37: Evolution 11 | C37: =_xlfn.CONCAT("Evolution visée pour les ",INDIRECT("'Parcs types'!D"&D37)) -> Evolution visée pour les VUL Essence <=3,5t (Crit'Air 3) | D37: 17 | E37: =_xlfn.CONCAT(LEFT(B37,3),RIGHT(B37,2),"Vis") -> Evo11Vis | F37: number | G37: {=IF((INDEX('Remplissage - Sit. Init.'!$C$23:$I$472,MATCH((_xlfn.CONCAT("Catégorie "&RIGHT(B37,2)))&('Remplissage - Sit. Init.'!$D$30),('Remplissage - Sit. Init.'!$C$23:$C$472)&('Remplissage - Sit. Init.'!$D$23:$D$472),0),7))>0,1,0)} -> 0 | J37: % | L37: La valeur à indiquer ici, est le pourcentage d'augmentation de la catégorie de véhicule (nombre de véhicule et nombre de kilomètre)
