Workbook

Sheet Accueil
D6: Description de l'outil
C9: Ce tableur a pour objectif de récolter les résultats de multiples actions d'une charte d'un EPCI, dans le cadre du programme InTerLUD+.
C10: L'outil agrège les données, calcule des résultats manquants par interpolation, et synthétise les résultats global de la charte.
D14: Versions de l'outil
C17: Version | D17: Détail | E17: Date | F17: Par
C18: V1 | D18: • Premier jet : onglet des données d'entrée, traitement de ces données, interpolations linéaires, gains | E18: 46057 | F18: BL évolution
C19: V2 | D19: • 1. Données d'entrée : Ajout de deux colonnes pour accueillir 3 duplicatas d'action 1. Données d'entrée : Ajout des données de plage temporelle • Partout : suppression de Réf pr ex-post, plus qu'une situation de référence • 2. Mise en forme données entrée : Modifications pour correspondre aux nouvelles données d'entrée (1 sit réf, 3 duplicatas) • 2. Mise en forme données entrée : les données des situations Réf, Prév, Expost sont égales à la donnée de la situation initiale pour la première année de donnée • 3. Émissions par action : Calculs pour le total de l'action + ses 3 duplicatas • 3. Émissions par action : Passage à 4 situations (au lieu de 5) • 3. Émissions par action : Ajout des évolutions des émissions en %, et des émissions cumulées • 4. Gains par action : Calculs pour le total de l'action + ses 3 duplicatas • 4. Gains par action : Passage à 4 situations (au lieu de 5) • 4. Gains par action : Ajout des gains cumulés sur une période | E19: 46091 | F19: BL évolution
D25: TODO
C28: OK | D28: Gérer l'existence de plusieurs valeurs pour une même année ?
D29: Implémenter toutes les actions (seulement B2 pour les résultats actuellement)

Sheet 1. Données d'entrée
C2: Données d'entrée
D11: ID | E11: Action | F11: Type émission | G11: Situation | H11: Année | I11: Valeur 1 | J11: Valeur 2 | K11: Valeur 3
C12: =ROW(C12) -> 12 | D12: =E12 & "-" & F12 & "-" & G12 & "-" & H12 -> B2-GES-Init-2010 | E12: B2 | F12: GES | G12: Init | H12: 2010
D13: =E13 & "-" & F13 & "-" & G13 & "-" & H13 -> B2-GES-Init-2011 | E13: =E12 -> B2 | F13: =F12 -> GES | G13: =G12 -> Init | H13: =H12+1 -> 2011
D14: =E14 & "-" & F14 & "-" & G14 & "-" & H14 -> B2-GES-Init-2012 | E14: =E13 -> B2 | F14: =F13 -> GES | G14: =G13 -> Init | H14: =H13+1 -> 2012
D15: =E15 & "-" & F15 & "-" & G15 & "-" & H15 -> B2-GES-Init-2013 | E15: =E14 -> B2 | F15: =F14 -> GES | G15: =G14 -> Init | H15: =H14+1 -> 2013
D16: =E16 & "-" & F16 & "-" & G16 & "-" & H16 -> B2-GES-Init-2014 | E16: =E15 -> B2 | F16: =F15 -> GES | G16: =G15 -> Init | H16: =H15+1 -> 2014
D17: =E17 & "-" & F17 & "-" & G17 & "-" & H17 -> B2-GES-Init-2015 | E17: =E16 -> B2 | F17: =F16 -> GES | G17: =G16 -> Init | H17: =H16+1 -> 2015
D18: =E18 & "-" & F18 & "-" & G18 & "-" & H18 -> B2-GES-Init-2016 | E18: =E17 -> B2 | F18: =F17 -> GES | G18: =G17 -> Init | H18: =H17+1 -> 2016
D19: =E19 & "-" & F19 & "-" & G19 & "-" & H19 -> B2-GES-Init-2017 | E19: =E18 -> B2 | F19: =F18 -> GES | G19: =G18 -> Init | H19: =H18+1 -> 2017
D20: =E20 & "-" & F20 & "-" & G20 & "-" & H20 -> B2-GES-Init-2018 | E20: =E19 -> B2 | F20: =F19 -> GES | G20: =G19 -> Init | H20: =H19+1 -> 2018
D21: =E21 & "-" & F21 & "-" & G21 & "-" & H21 -> B2-GES-Init-2019 | E21: =E20 -> B2 | F21: =F20 -> GES | G21: =G20 -> Init | H21: =H20+1 -> 2019
D22: =E22 & "-" & F22 & "-" & G22 & "-" & H22 -> B2-GES-Init-2020 | E22: =E21 -> B2 | F22: =F21 -> GES | G22: =G21 -> Init | H22: =H21+1 -> 2020
D23: =E23 & "-" & F23 & "-" & G23 & "-" & H23 -> B2-GES-Init-2021 | E23: =E22 -> B2 | F23: =F22 -> GES | G23: =G22 -> Init | H23: =H22+1 -> 2021
D24: =E24 & "-" & F24 & "-" & G24 & "-" & H24 -> B2-GES-Init-2022 | E24: =E23 -> B2 | F24: =F23 -> GES | G24: =G23 -> Init | H24: =H23+1 -> 2022
... D52: =E52 & "-" & F52 & "-" & G52 & "-" & H52 -> B2-GES-Init-2050 | E52: =E51 -> B2 | F52: =F51 -> GES | G52: =G51 -> Init | H52: =H51+1 -> 2050
D53: =E53 & "-" & F53 & "-" & G53 & "-" & H53 -> B2-GES-Réf-2010 | E53: =E52 -> B2 | F53: =F52 -> GES | G53: Réf | H53: 2010
D54: =E54 & "-" & F54 & "-" & G54 & "-" & H54 -> B2-GES-Réf-2011 | E54: =E53 -> B2 | F54: =F53 -> GES | G54: =G53 -> Réf | H54: =H53+1 -> 2011
D55: =E55 & "-" & F55 & "-" & G55 & "-" & H55 -> B2-GES-Réf-2012 | E55: =E54 -> B2 | F55: =F54 -> GES | G55: =G54 -> Réf | H55: =H54+1 -> 2012
D56: =E56 & "-" & F56 & "-" & G56 & "-" & H56 -> B2-GES-Réf-2013 | E56: =E55 -> B2 | F56: =F55 -> GES | G56: =G55 -> Réf | H56: =H55+1 -> 2013
D57: =E57 & "-" & F57 & "-" & G57 & "-" & H57 -> B2-GES-Réf-2014 | E57: =E56 -> B2 | F57: =F56 -> GES | G57: =G56 -> Réf | H57: =H56+1 -> 2014
D58: =E58 & "-" & F58 & "-" & G58 & "-" & H58 -> B2-GES-Réf-2015 | E58: =E57 -> B2 | F58: =F57 -> GES | G58: =G57 -> Réf | H58: =H57+1 -> 2015
D59: =E59 & "-" & F59 & "-" & G59 & "-" & H59 -> B2-GES-Réf-2016 | E59: =E58 -> B2 | F59: =F58 -> GES | G59: =G58 -> Réf | H59: =H58+1 -> 2016
D60: =E60 & "-" & F60 & "-" & G60 & "-" & H60 -> B2-GES-Réf-2017 | E60: =E59 -> B2 | F60: =F59 -> GES | G60: =G59 -> Réf | H60: =H59+1 -> 2017
D61: =E61 & "-" & F61 & "-" & G61 & "-" & H61 -> B2-GES-Réf-2018 | E61: =E60 -> B2 | F61: =F60 -> GES | G61: =G60 -> Réf | H61: =H60+1 -> 2018
D62: =E62 & "-" & F62 & "-" & G62 & "-" & H62 -> B2-GES-Réf-2019 | E62: =E61 -> B2 | F62: =F61 -> GES | G62: =G61 -> Réf | H62: =H61+1 -> 2019
D63: =E63 & "-" & F63 & "-" & G63 & "-" & H63 -> B2-GES-Réf-2020 | E63: =E62 -> B2 | F63: =F62 -> GES | G63: =G62 -> Réf | H63: =H62+1 -> 2020
D64: =E64 & "-" & F64 & "-" & G64 & "-" & H64 -> B2-GES-Réf-2021 | E64: =E63 -> B2 | F64: =F63 -> GES | G64: =G63 -> Réf | H64: =H63+1 -> 2021
D65: =E65 & "-" & F65 & "-" & G65 & "-" & H65 -> B2-GES-Réf-2022 | E65: =E64 -> B2 | F65: =F64 -> GES | G65: =G64 -> Réf | H65: =H64+1 -> 2022
... D93: =E93 & "-" & F93 & "-" & G93 & "-" & H93 -> B2-GES-Réf-2050 | E93: =E92 -> B2 | F93: =F92 -> GES | G93: =G92 -> Réf | H93: =H92+1 -> 2050
D94: =E94 & "-" & F94 & "-" & G94 & "-" & H94 -> B2-GES-Prév-2010 | E94: =E93 -> B2 | F94: =F93 -> GES | G94: Prév | H94: 2010
D95: =E95 & "-" & F95 & "-" & G95 & "-" & H95 -> B2-GES-Prév-2011 | E95: =E94 -> B2 | F95: =F94 -> GES | G95: =G94 -> Prév | H95: =H94+1 -> 2011
D96: =E96 & "-" & F96 & "-" & G96 & "-" & H96 -> B2-GES-Prév-2012 | E96: =E95 -> B2 | F96: =F95 -> GES | G96: =G95 -> Prév | H96: =H95+1 -> 2012
D97: =E97 & "-" & F97 & "-" & G97 & "-" & H97 -> B2-GES-Prév-2013 | E97: =E96 -> B2 | F97: =F96 -> GES | G97: =G96 -> Prév | H97: =H96+1 -> 2013
D98: =E98 & "-" & F98 & "-" & G98 & "-" & H98 -> B2-GES-Prév-2014 | E98: =E97 -> B2 | F98: =F97 -> GES | G98: =G97 -> Prév | H98: =H97+1 -> 2014
D99: =E99 & "-" & F99 & "-" & G99 & "-" & H99 -> B2-GES-Prév-2015 | E99: =E98 -> B2 | F99: =F98 -> GES | G99: =G98 -> Prév | H99: =H98+1 -> 2015
D100: =E100 & "-" & F100 & "-" & G100 & "-" & H100 -> B2-GES-Prév-2016 | E100: =E99 -> B2 | F100: =F99 -> GES | G100: =G99 -> Prév | H100: =H99+1 -> 2016
D101: =E101 & "-" & F101 & "-" & G101 & "-" & H101 -> B2-GES-Prév-2017 | E101: =E100 -> B2 | F101: =F100 -> GES | G101: =G100 -> Prév | H101: =H100+1 -> 2017
D102: =E102 & "-" & F102 & "-" & G102 & "-" & H102 -> B2-GES-Prév-2018 | E102: =E101 -> B2 | F102: =F101 -> GES | G102: =G101 -> Prév | H102: =H101+1 -> 2018
D103: =E103 & "-" & F103 & "-" & G103 & "-" & H103 -> B2-GES-Prév-2019 | E103: =E102 -> B2 | F103: =F102 -> GES | G103: =G102 -> Prév | H103: =H102+1 -> 2019
...

Sheet 2. Mise en forme données entrée
B2: Mise en forme des données d'entrée
E10: Numéros lignes pour trouver données dans 1. Données d'entrée | AK10: Numéros lignes pour trouver données dans 1. Données d'entrée | BQ10: Numéros lignes pour trouver données dans 1. Données d'entrée
C13: Impacts | D13: Ligne
C14: GES | D14: =$D$39 * $D$40 * (E14-1) -> 0 | E14: 1
C15: PM | D15: =$D$39 * $D$40 * (E15-1) -> 164 | E15: 2
C16: NOx | D16: =$D$39 * $D$40 * (E16-1) -> 328 | E16: 3
C17: HC | D17: =$D$39 * $D$40 * (E17-1) -> 492 | E17: 4
C18: CO | D18: =$D$39 * $D$40 * (E18-1) -> 656 | E18: 5
C19: Nrj | D19: =$D$39 * $D$40 * (E19-1) -> 820 | E19: 6
C21: Situations
C22: Init | D22: =$D$39 * (E22-1) -> 0 | E22: 1
C23: Référence | D23: =$D$39 * (E23-1) -> 41 | E23: 2
C24: Prév | D24: =$D$39 * (E24-1) -> 82 | E24: 3
C25: Expost | D25: =$D$39 * (E25-1) -> 123 | E25: 4
C27: Actions
C28: B2 | D28: =$D$42 + $D$39 * $D$40 * $D$41 * (E28-1) -> 12 | E28: 1
C29: B3 | D29: =$D$42 + $D$39 * $D$40 * $D$41 * (E29-1) -> 996 | E29: 2
C30: B4 | D30: =$D$42 + $D$39 * $D$40 * $D$41 * (E30-1) -> 1980 | E30: 3
C31: C1 | D31: =$D$42 + $D$39 * $D$40 * $D$41 * (E31-1) -> 2964 | E31: 4
C32: C2 | D32: =$D$42 + $D$39 * $D$40 * $D$41 * (E32-1) -> 3948 | E32: 5
C33: C3 | D33: =$D$42 + $D$39 * $D$40 * $D$41 * (E33-1) -> 4932 | E33: 6
C34: C4 | D34: =$D$42 + $D$39 * $D$40 * $D$41 * (E34-1) -> 5916 | E34: 7
C35: C6 | D35: =$D$42 + $D$39 * $D$40 * $D$41 * (E35-1) -> 6900 | E35: 8
C36: C7 | D36: =$D$42 + $D$39 * $D$40 * $D$41 * (E36-1) -> 7884 | E36: 9
C37: C9 | D37: =$D$42 + $D$39 * $D$40 * $D$41 * (E37-1) -> 8868 | E37: 10
C39: Nombre années | D39: 41
C40: Nombre situations | D40: 4
C41: Nombre impacts | D41: 6
C42: Offset | D42: ='1. Données d''entrée'!C12 -> 12
B46: =VLOOKUP(C46, $C$28:$D$37, 2, FALSE) -> 12 | C46: B2 | D46: - Améliorez l’efficacité de vos aires de livraisons
D48: 1 | AJ48: 2 | BP48: 3
D49: VALEUR 1 | E49: {=IFERROR(_xlfn.XLOOKUP(TRUE,E53:E93 > 0, $C53:$C93), $C53)} -> 2025 | F49: =E49 -> 2025 | G49: =F49 -> 2025 | H49: =G49 -> 2025 | J49: {=IFERROR(_xlfn.XLOOKUP(TRUE,J53:J93 > 0, $C53:$C93), $C53)} -> 2025 | K49: =J49 -> 2025 | L49: =K49 -> 2025 | M49: =L49 -> 2025 | O49: {=IFERROR(_xlfn.XLOOKUP(TRUE,O53:O93 > 0, $C53:$C93), $C53)} -> 2025 | P49: =O49 -> 2025 | Q49: =P49 -> 2025 | R49: =Q49 -> 2025 | T49: {=IFERROR(_xlfn.XLOOKUP(TRUE,T53:T93 > 0, $C53:$C93), $C53)} -> 2025 | U49: =T49 -> 2025 | V49: =U49 -> 2025 | W49: =V49 -> 2025 | Y49: {=IFERROR(_xlfn.XLOOKUP(TRUE,Y53:Y93 > 0, $C53:$C93), $C53)} -> 2025 | Z49: =Y49 -> 2025 | AA49: =Z49 -> 2025 | AB49: =AA49 -> 2025 | AD49: {=IFERROR(_xlfn.XLOOKUP(TRUE,AD53:AD93 > 0, $C53:$C93), $C53)} -> 2025 | AE49: =AD49 -> 2025 | AF49: =AE49 -> 2025 | AG49: =AF49 -> 2025 | AJ49: VALEUR 2 | AK49: {=IFERROR(_xlfn.XLOOKUP(TRUE,AK53:AK93 > 0, $C53:$C93), $C53)} -> 2010 | AL49: =AK49 -> 2010 | AM49: =AL49 -> 2010 | AN49: =AM49 -> 2010 | AP49: {=IFERROR(_xlfn.XLOOKUP(TRUE,AP53:AP93 > 0, $C53:$C93), $C53)} -> 2010 | AQ49: =AP49 -> 2010 | AR49: =AQ49 -> 2010 | AS49: =AR49 -> 2010 | AU49: {=IFERROR(_xlfn.XLOOKUP(TRUE,AU53:AU93 > 0, $C53:$C93), $C53)} -> 2010 | AV49: =AU49 -> 2010 | AW49: =AV49 -> 2010 | AX49: =AW49 -> 2010 | AZ49: {=IFERROR(_xlfn.XLOOKUP(TRUE,AZ53:AZ93 > 0, $C53:$C93), $C53)} -> 2010 | BA49: =AZ49 -> 2010 | BB49: =BA49 -> 2010 | BC49: =BB49 -> 2010 | BE49: {=IFERROR(_xlfn.XLOOKUP(TRUE,BE53:BE93 > 0, $C53:$C93), $C53)} -> 2010 | BF49: =BE49 -> 2010 | BG49: =BF49 -> 2010 | BH49: =BG49 -> 2010 | BJ49: {=IFERROR(_xlfn.XLOOKUP(TRUE,BJ53:BJ93 > 0, $C53:$C93), $C53)} -> 2010 | BK49: =BJ49 -> 2010 | BL49: =BK49 -> 2010 | BM49: =BL49 -> 2010 | BP49: VALEUR 3 | BQ49: {=IFERROR(_xlfn.XLOOKUP(TRUE,BQ53:BQ93 > 0, $C53:$C93), $C53)} -> 2010 | BR49: =BQ49 -> 2010 | BS49: =BR49 -> 2010 | BT49: =BS49 -> 2010 | BV49: {=IFERROR(_xlfn.XLOOKUP(TRUE,BV53:BV93 > 0, $C53:$C93), $C53)} -> 2010 | BW49: =BV49 -> 2010 | BX49: =BW49 -> 2010 | BY49: =BX49 -> 2010 | CA49: {=IFERROR(_xlfn.XLOOKUP(TRUE,CA53:CA93 > 0, $C53:$C93), $C53)} -> 2010 | CB49: =CA49 -> 2010 | CC49: =CB49 -> 2010 | CD49: =CC49 -> 2010 | CF49: {=IFERROR(_xlfn.XLOOKUP(TRUE,CF53:CF93 > 0, $C53:$C93), $C53)} -> 2010 | CG49: =CF49 -> 2010 | CH49: =CG49 -> 2010 | CI49: =CH49 -> 2010 | CK49: {=IFERROR(_xlfn.XLOOKUP(TRUE,CK53:CK93 > 0, $C53:$C93), $C53)} -> 2010 | CL49: =CK49 -> 2010 | CM49: =CL49 -> 2010 | CN49: =CM49 -> 2010 | CP49: {=IFERROR(_xlfn.XLOOKUP(TRUE,CP53:CP93 > 0, $C53:$C93), $C53)} -> 2010 | CQ49: =CP49 -> 2010 | CR49: =CQ49 -> 2010 | CS49: =CR49 -> 2010
E50: GES | I50: =VLOOKUP(E50, $C$14:$D$19, 2, FALSE) -> 0 | J50: PM | N50: =VLOOKUP(J50, $C$14:$D$19, 2, FALSE) -> 164 | O50: NOx | S50: =VLOOKUP(O50, $C$14:$D$19, 2, FALSE) -> 328 | T50: HC | X50: =VLOOKUP(T50, $C$14:$D$19, 2, FALSE) -> 492 | Y50: CO | AC50: =VLOOKUP(Y50, $C$14:$D$19, 2, FALSE) -> 656 | AD50: Nrj | AH50: =VLOOKUP(AD50, $C$14:$D$19, 2, FALSE) -> 820 | AK50: GES | AO50: =VLOOKUP(AK50, $C$14:$D$19, 2, FALSE) -> 0 | AP50: PM | AT50: =VLOOKUP(AP50, $C$14:$D$19, 2, FALSE) -> 164 | AU50: NOx | AY50: =VLOOKUP(AU50, $C$14:$D$19, 2, FALSE) -> 328 | AZ50: HC | BD50: =VLOOKUP(AZ50, $C$14:$D$19, 2, FALSE) -> 492 | BE50: CO | BI50: =VLOOKUP(BE50, $C$14:$D$19, 2, FALSE) -> 656 | BJ50: Nrj | BN50: =VLOOKUP(BJ50, $C$14:$D$19, 2, FALSE) -> 820 | BQ50: GES | BU50: =VLOOKUP(BQ50, $C$14:$D$19, 2, FALSE) -> 0 | BV50: PM | BZ50: =VLOOKUP(BV50, $C$14:$D$19, 2, FALSE) -> 164 | CA50: NOx | CE50: =VLOOKUP(CA50, $C$14:$D$19, 2, FALSE) -> 328 | CF50: HC | CJ50: =VLOOKUP(CF50, $C$14:$D$19, 2, FALSE) -> 492 | CK50: CO | CO50: =VLOOKUP(CK50, $C$14:$D$19, 2, FALSE) -> 656 | CP50: Nrj | CT50: =VLOOKUP(CP50, $C$14:$D$19, 2, FALSE) -> 820
E51: {=TRANSPOSE($D$22:$D$25)} -> 0 | F51: 41 | G51: 82 | H51: 123 | J51: {=TRANSPOSE($D$22:$D$25)} -> 0 | K51: 41 | L51: 82 | M51: 123 | O51: {=TRANSPOSE($D$22:$D$25)} -> 0 | P51: 41 | Q51: 82 | R51: 123 | T51: {=TRANSPOSE($D$22:$D$25)} -> 0 | U51: 41 | V51: 82 | W51: 123 | Y51: {=TRANSPOSE($D$22:$D$25)} -> 0 | Z51: 41 | AA51: 82 | AB51: 123 | AD51: {=TRANSPOSE($D$22:$D$25)} -> 0 | AE51: 41 | AF51: 82 | AG51: 123 | AK51: {=TRANSPOSE($D$22:$D$25)} -> 0 | AL51: 41 | AM51: 82 | AN51: 123 | AP51: {=TRANSPOSE($D$22:$D$25)} -> 0 | AQ51: 41 | AR51: 82 | AS51: 123 | AU51: {=TRANSPOSE($D$22:$D$25)} -> 0 | AV51: 41 | AW51: 82 | AX51: 123 | AZ51: {=TRANSPOSE($D$22:$D$25)} -> 0 | BA51: 41 | BB51: 82 | BC51: 123 | BE51: {=TRANSPOSE($D$22:$D$25)} -> 0 | BF51: 41 | BG51: 82 | BH51: 123 | BJ51: {=TRANSPOSE($D$22:$D$25)} -> 0 | BK51: 41 | BL51: 82 | BM51: 123 | BQ51: {=TRANSPOSE($D$22:$D$25)} -> 0 | BR51: 41 | BS51: 82 | BT51: 123 | BV51: {=TRANSPOSE($D$22:$D$25)} -> 0 | BW51: 41 | BX51: 82 | BY51: 123 | CA51: {=TRANSPOSE($D$22:$D$25)} -> 0 | CB51: 41 | CC51: 82 | CD51: 123 | CF51: {=TRANSPOSE($D$22:$D$25)} -> 0 | CG51: 41 | CH51: 82 | CI51: 123 | CK51: {=TRANSPOSE($D$22:$D$25)} -> 0 | CL51: 41 | CM51: 82 | CN51: 123 | CP51: {=TRANSPOSE($D$22:$D$25)} -> 0 | CQ51: 41 | CR51: 82 | CS51: 123
C52: Situation → Année ↓ | E52: Initiale | F52: Référence | G52: Prévisionnelle | H52: Ex-post | J52: Initiale | K52: Référence | L52: Prévisionnelle | M52: Ex-post | O52: Initiale | P52: Référence | Q52: Prévisionnelle | R52: Ex-post | T52: Initiale | U52: Référence | V52: Prévisionnelle | W52: Ex-post | Y52: Initiale | Z52: Référence | AA52: Prévisionnelle | AB52: Ex-post | AD52: Initiale | AE52: Référence | AF52: Prévisionnelle | AG52: Ex-post | AK52: Initiale | AL52: Référence | AM52: Prévisionnelle | AN52: Ex-post | AP52: Initiale | AQ52: Référence | AR52: Prévisionnelle | AS52: Ex-post | AU52: Initiale | AV52: Référence | AW52: Prévisionnelle | AX52: Ex-post | AZ52: Initiale | BA52: Référence | BB52: Prévisionnelle | BC52: Ex-post | BE52: Initiale | BF52: Référence | BG52: Prévisionnelle | BH52: Ex-post | BJ52: Initiale | BK52: Référence | BL52: Prévisionnelle | BM52: Ex-post | BQ52: Initiale | BR52: Référence | BS52: Prévisionnelle | BT52: Ex-post | BV52: Initiale | BW52: Référence | BX52: Prévisionnelle | BY52: Ex-post | CA52: Initiale | CB52: Référence | CC52: Prévisionnelle | CD52: Ex-post | CF52: Initiale | CG52: Référence | CH52: Prévisionnelle | CI52: Ex-post | CK52: Initiale | CL52: Référence | CM52: Prévisionnelle | CN52: Ex-post | CP52: Initiale | CQ52: Référence | CR52: Prévisionnelle | CS52: Ex-post
B53: 0 | C53: 2010 | E53: {=INDEX('1. Données d''entrée'!$I:$K, B46 + I50 + E51 + $B53, D48)} -> 0 | F53: {=IF($C53 <= F49, E53, INDEX('1. Données d''entrée'!$I:$K, B46 + I50 + F51 + $B53, D48))} -> 0 | G53: {=IF($C53 <= G$49, E53, INDEX('1. Données d''entrée'!$I:$K, B46 + I50 + G51 + $B53, D48))} -> 0 | H53: {=IF($C53 <= H$49, E53, INDEX('1. Données d''entrée'!$I:$K, B46 + I50 + H51 + $B53, D48))} -> 0 | J53: {=INDEX('1. Données d''entrée'!$I:$K, B46 + N50 + J51 + $B53, D48)} -> 0 | K53: {=IF($C53 <= K49, J53, INDEX('1. Données d''entrée'!$I:$K, B46 + N50 + K51 + $B53, D48))} -> 0 | L53: {=IF($C53 <= L$49, J53, INDEX('1. Données d''entrée'!$I:$K, B46 + N50 + L51 + $B53, D48))} -> 0 | M53: {=IF($C53 <= M$49, J53, INDEX('1. Données d''entrée'!$I:$K, B46 + N50 + M51 + $B53, D48))} -> 0 | O53: {=INDEX('1. Données d''entrée'!$I:$K, B46 + S50 + O51 + $B53, D48)} -> 0 | P53: {=IF($C53 <= P49, O53, INDEX('1. Données d''entrée'!$I:$K, B46 + S50 + P51 + $B53, D48))} -> 0 | Q53: {=IF($C53 <= Q$49, O53, INDEX('1. Données d''entrée'!$I:$K, B46 + S50 + Q51 + $B53, D48))} -> 0 | R53: {=IF($C53 <= R$49, O53, INDEX('1. Données d''entrée'!$I:$K, B46 + S50 + R51 + $B53, D48))} -> 0 | T53: {=INDEX('1. Données d''entrée'!$I:$K, B46 + X50 + T51 + $B53, D48)} -> 0 | U53: {=IF($C53 <= U49, T53, INDEX('1. Données d''entrée'!$I:$K, B46 + X50 + U51 + $B53, D48))} -> 0 | V53: {=IF($C53 <= V$49, T53, INDEX('1. Données d''entrée'!$I:$K, B46 + X50 + V51 + $B53, D48))} -> 0 | W53: {=IF($C53 <= W$49, T53, INDEX('1. Données d''entrée'!$I:$K, B46 + X50 + W51 + $B53, D48))} -> 0 | Y53: {=INDEX('1. Données d''entrée'!$I:$K, B46 + AC50 + Y51 + $B53, D48)} -> 0 | Z53: {=IF($C53 <= Z49, Y53, INDEX('1. Données d''entrée'!$I:$K, B46 + AC50 + Z51 + $B53, D48))} -> 0 | AA53: {=IF($C53 <= AA$49, Y53, INDEX('1. Données d''entrée'!$I:$K, B46 + AC50 + AA51 + $B53, D48))} -> 0 | AB53: {=IF($C53 <= AB$49, Y53, INDEX('1. Données d''entrée'!$I:$K, B46 + AC50 + AB51 + $B53, D48))} -> 0 | AD53: {=INDEX('1. Données d''entrée'!$I:$K, B46 + AH50 + AD51 + $B53, D48)} -> 0 | AE53: {=IF($C53 <= AE49, AD53, INDEX('1. Données d''entrée'!$I:$K, B46 + AH50 + AE51 + $B53, D48))} -> 0 | AF53: {=IF($C53 <= AF$49, AD53, INDEX('1. Données d''entrée'!$I:$K, B46 + AH50 + AF51 + $B53, D48))} -> 0 | AG53: {=IF($C53 <= AG$49, AD53, INDEX('1. Données d''entrée'!$I:$K, B46 + AH50 + AG51 + $B53, D48))} -> 0 | AK53: {=INDEX('1. Données d''entrée'!$I:$K, B46 + AO50 + AK51 + $B53, AJ48)} -> 0 | AL53: {=IF($C53 <= AL49, AK53, INDEX('1. Données d''entrée'!$I:$K, B46 + AO50 + AL51 + $B53, AJ48))} -> 0 | AM53: {=IF($C53 <= AM$49, AK53, INDEX('1. Données d''entrée'!$I:$K, B46 + AO50 + AM51 + $B53, AJ48))} -> 0 | AN53: {=IF($C53 <= AN$49, AK53, INDEX('1. Données d''entrée'!$I:$K, B46 + AO50 + AN51 + $B53, AJ48))} -> 0 | AP53: {=INDEX('1. Données d''entrée'!$I:$K, B46 + AT50 + AP51 + $B53, AJ48)} -> 0 | AQ53: {=IF($C53 <= AQ49, AP53, INDEX('1. Données d''entrée'!$I:$K, B46 + AT50 + AQ51 + $B53, AJ48))} -> 0 | AR53: {=IF($C53 <= AR$49, AP53, INDEX('1. Données d''entrée'!$I:$K, B46 + AT50 + AR51 + $B53, AJ48))} -> 0 | AS53: {=IF($C53 <= AS$49, AP53, INDEX('1. Données d''entrée'!$I:$K, B46 + AT50 + AS51 + $B53, AJ48))} -> 0 | AU53: {=INDEX('1. Données d''entrée'!$I:$K, B46 + AY50 + AU51 + $B53, AJ48)} -> 0 | AV53: {=IF($C53 <= AV49, AU53, INDEX('1. Données d''entrée'!$I:$K, B46 + AY50 + AV51 + $B53, AJ48))} -> 0 | AW53: {=IF($C53 <= AW$49, AU53, INDEX('1. Données d''entrée'!$I:$K, B46 + AY50 + AW51 + $B53, AJ48))} -> 0 | AX53: {=IF($C53 <= AX$49, AU53, INDEX('1. Données d''entrée'!$I:$K, B46 + AY50 + AX51 + $B53, AJ48))} -> 0 | AZ53: {=INDEX('1. Données d''entrée'!$I:$K, B46 + BD50 + AZ51 + $B53, AJ48)} -> 0 | BA53: {=IF($C53 <= BA49, AZ53, INDEX('1. Données d''entrée'!$I:$K, B46 + BD50 + BA51 + $B53, AJ48))} -> 0 | BB53: {=IF($C53 <= BB$49, AZ53, INDEX('1. Données d''entrée'!$I:$K, B46 + BD50 + BB51 + $B53, AJ48))} -> 0 | BC53: {=IF($C53 <= BC$49, AZ53, INDEX('1. Données d''entrée'!$I:$K, B46 + BD50 + BC51 + $B53, AJ48))} -> 0 | BE53: {=INDEX('1. Données d''entrée'!$I:$K, B46 + BI50 + BE51 + $B53, AJ48)} -> 0 | BF53: {=IF($C53 <= BF49, BE53, INDEX('1. Données d''entrée'!$I:$K, B46 + BI50 + BF51 + $B53, AJ48))} -> 0 | BG53: {=IF($C53 <= BG$49, BE53, INDEX('1. Données d''entrée'!$I:$K, B46 + BI50 + BG51 + $B53, AJ48))} -> 0 | BH53: {=IF($C53 <= BH$49, BE53, INDEX('1. Données d''entrée'!$I:$K, B46 + BI50 + BH51 + $B53, AJ48))} -> 0 | BJ53: {=INDEX('1. Données d''entrée'!$I:$K, B46 + BN50 + BJ51 + $B53, AJ48)} -> 0 | BK53: {=IF($C53 <= BK49, BJ53, INDEX('1. Données d''entrée'!$I:$K, B46 + BN50 + BK51 + $B53, AJ48))} -> 0 | BL53: {=IF($C53 <= BL$49, BJ53, INDEX('1. Données d''entrée'!$I:$K, B46 + BN50 + BL51 + $B53, AJ48))} -> 0 | BM53: {=IF($C53 <= BM$49, BJ53, INDEX('1. Données d''entrée'!$I:$K, B46 + BN50 + BM51 + $B53, AJ48))} -> 0 | BQ53: {=INDEX('1. Données d''entrée'!$I:$K, B46 + BU50 + BQ51 + $B53, BP48)} -> 0 | BR53: {=IF($C53 <= BR49, BQ53, INDEX('1. Données d''entrée'!$I:$K, B46 + BU50 + BR51 + $B53, BP48))} -> 0 | BS53: {=IF($C53 <= BS$49, BQ53, INDEX('1. Données d''entrée'!$I:$K, B46 + BU50 + BS51 + $B53, BP48))} -> 0 | BT53: {=IF($C53 <= BT$49, BQ53, INDEX('1. Données d''entrée'!$I:$K, B46 + BU50 + BT51 + $B53, BP48))} -> 0 | BV53: {=INDEX('1. Données d''entrée'!$I:$K, B46 + BZ50 + BV51 + $B53, BP48)} -> 0 | BW53: {=IF($C53 <= BW49, BV53, INDEX('1. Données d''entrée'!$I:$K, B46 + BZ50 + BW51 + $B53, BP48))} -> 0 | BX53: {=IF($C53 <= BX$49, BV53, INDEX('1. Données d''entrée'!$I:$K, B46 + BZ50 + BX51 + $B53, BP48))} -> 0 | BY53: {=IF($C53 <= BY$49, BV53, INDEX('1. Données d''entrée'!$I:$K, B46 + BZ50 + BY51 + $B53, BP48))} -> 0 | CA53: {=INDEX('1. Données d''entrée'!$I:$K, B46 + CE50 + CA51 + $B53, BP48)} -> 0 | CB53: {=IF($C53 <= CB49, CA53, INDEX('1. Données d''entrée'!$I:$K, B46 + CE50 + CB51 + $B53, BP48))} -> 0 | CC53: {=IF($C53 <= CC$49, CA53, INDEX('1. Données d''entrée'!$I:$K, B46 + CE50 + CC51 + $B53, BP48))} -> 0 | CD53: {=IF($C53 <= CD$49, CA53, INDEX('1. Données d''entrée'!$I:$K, B46 + CE50 + CD51 + $B53, BP48))} -> 0 | CF53: {=INDEX('1. Données d''entrée'!$I:$K, B46 + CJ50 + CF51 + $B53, BP48)} -> 0 | CG53: {=IF($C53 <= CG49, CF53, INDEX('1. Données d''entrée'!$I:$K, B46 + CJ50 + CG51 + $B53, BP48))} -> 0 | CH53: {=IF($C53 <= CH$49, CF53, INDEX('1. Données d''entrée'!$I:$K, B46 + CJ50 + CH51 + $B53, BP48))} -> 0 | CI53: {=IF($C53 <= CI$49, CF53, INDEX('1. Données d''entrée'!$I:$K, B46 + CJ50 + CI51 + $B53, BP48))} -> 0 | CK53: {=INDEX('1. Données d''entrée'!$I:$K, B46 + CO50 + CK51 + $B53, BP48)} -> 0 | CL53: {=IF($C53 <= CL49, CK53, INDEX('1. Données d''entrée'!$I:$K, B46 + CO50 + CL51 + $B53, BP48))} -> 0 | CM53: {=IF($C53 <= CM$49, CK53, INDEX('1. Données d''entrée'!$I:$K, B46 + CO50 + CM51 + $B53, BP48))} -> 0 | CN53: {=IF($C53 <= CN$49, CK53, INDEX('1. Données d''entrée'!$I:$K, B46 + CO50 + CN51 + $B53, BP48))} -> 0 | CP53: {=INDEX('1. Données d''entrée'!$I:$K, B46 + CT50 + CP51 + $B53, BP48)} -> 0 | CQ53: {=IF($C53 <= CQ49, CP53, INDEX('1. Données d''entrée'!$I:$K, B46 + CT50 + CQ51 + $B53, BP48))} -> 0 | CR53: {=IF($C53 <= CR$49, CP53, INDEX('1. Données d''entrée'!$I:$K, B46 + CT50 + CR51 + $B53, BP48))} -> 0 | CS53: {=IF($C53 <= CS$49, CP53, INDEX('1. Données d''entrée'!$I:$K, B46 + CT50 + CS51 + $B53, BP48))} -> 0
B54: 1 | C54: 2011 | E54: {=INDEX('1. Données d''entrée'!$I:$K, B46 + I50 + E51 + $B54, D48)} -> 0 | F54: {=IF($C54 <= F49, E54, INDEX('1. Données d''entrée'!$I:$K, B46 + I50 + F51 + $B54, D48))} -> 0 | G54: {=IF($C54 <= G$49, E54, INDEX('1. Données d''entrée'!$I:$K, B46 + I50 + G51 + $B54, D48))} -> 0 | H54: {=IF($C54 <= H$49, E54, INDEX('1. Données d''entrée'!$I:$K, B46 + I50 + H51 + $B54, D48))} -> 0 | J54: {=INDEX('1. Données d''entrée'!$I:$K, B46 + N50 + J51 + $B54, D48)} -> 0 | K54: {=IF($C54 <= K49, J54, INDEX('1. Données d''entrée'!$I:$K, B46 + N50 + K51 + $B54, D48))} -> 0 | L54: {=IF($C54 <= L$49, J54, INDEX('1. Données d''entrée'!$I:$K, B46 + N50 + L51 + $B54, D48))} -> 0 | M54: {=IF($C54 <= M$49, J54, INDEX('1. Données d''entrée'!$I:$K, B46 + N50 + M51 + $B54, D48))} -> 0 | O54: {=INDEX('1. Données d''entrée'!$I:$K, B46 + S50 + O51 + $B54, D48)} -> 0 | P54: {=IF($C54 <= P49, O54, INDEX('1. Données d''entrée'!$I:$K, B46 + S50 + P51 + $B54, D48))} -> 0 | Q54: {=IF($C54 <= Q$49, O54, INDEX('1. Données d''entrée'!$I:$K, B46 + S50 + Q51 + $B54, D48))} -> 0 | R54: {=IF($C54 <= R$49, O54, INDEX('1. Données d''entrée'!$I:$K, B46 + S50 + R51 + $B54, D48))} -> 0 | T54: {=INDEX('1. Données d''entrée'!$I:$K, B46 + X50 + T51 + $B54, D48)} -> 0 | U54: {=IF($C54 <= U49, T54, INDEX('1. Données d''entrée'!$I:$K, B46 + X50 + U51 + $B54, D48))} -> 0 | V54: {=IF($C54 <= V$49, T54, INDEX('1. Données d''entrée'!$I:$K, B46 + X50 + V51 + $B54, D48))} -> 0 | W54: {=IF($C54 <= W$49, T54, INDEX('1. Données d''entrée'!$I:$K, B46 + X50 + W51 + $B54, D48))} -> 0 | Y54: {=INDEX('1. Données d''entrée'!$I:$K, B46 + AC50 + Y51 + $B54, D48)} -> 0 | Z54: {=IF($C54 <= Z49, Y54, INDEX('1. Données d''entrée'!$I:$K, B46 + AC50 + Z51 + $B54, D48))} -> 0 | AA54: {=IF($C54 <= AA$49, Y54, INDEX('1. Données d''entrée'!$I:$K, B46 + AC50 + AA51 + $B54, D48))} -> 0 | AB54: {=IF($C54 <= AB$49, Y54, INDEX('1. Données d''entrée'!$I:$K, B46 + AC50 + AB51 + $B54, D48))} -> 0 | AD54: {=INDEX('1. Données d''entrée'!$I:$K, B46 + AH50 + AD51 + $B54, D48)} -> 0 | AE54: {=IF($C54 <= AE49, AD54, INDEX('1. Données d''entrée'!$I:$K, B46 + AH50 + AE51 + $B54, D48))} -> 0 | AF54: {=IF($C54 <= AF$49, AD54, INDEX('1. Données d''entrée'!$I:$K, B46 + AH50 + AF51 + $B54, D48))} -> 0 | AG54: {=IF($C54 <= AG$49, AD54, INDEX('1. Données d''entrée'!$I:$K, B46 + AH50 + AG51 + $B54, D48))} -> 0 | AK54: {=INDEX('1. Données d''entrée'!$I:$K, B46 + AO50 + AK51 + $B54, AJ48)} -> 0 | AL54: {=IF($C54 <= AL49, AK54, INDEX('1. Données d''entrée'!$I:$K, B46 + AO50 + AL51 + $B54, AJ48))} -> 0 | AM54: {=IF($C54 <= AM$49, AK54, INDEX('1. Données d''entrée'!$I:$K, B46 + AO50 + AM51 + $B54, AJ48))} -> 0 | AN54: {=IF($C54 <= AN$49, AK54, INDEX('1. Données d''entrée'!$I:$K, B46 + AO50 + AN51 + $B54, AJ48))} -> 0 | AP54: {=INDEX('1. Données d''entrée'!$I:$K, B46 + AT50 + AP51 + $B54, AJ48)} -> 0 | AQ54: {=IF($C54 <= AQ49, AP54, INDEX('1. Données d''entrée'!$I:$K, B46 + AT50 + AQ51 + $B54, AJ48))} -> 0 | AR54: {=IF($C54 <= AR$49, AP54, INDEX('1. Données d''entrée'!$I:$K, B46 + AT50 + AR51 + $B54, AJ48))} -> 0 | AS54: {=IF($C54 <= AS$49, AP54, INDEX('1. Données d''entrée'!$I:$K, B46 + AT50 + AS51 + $B54, AJ48))} -> 0 | AU54: {=INDEX('1. Données d''entrée'!$I:$K, B46 + AY50 + AU51 + $B54, AJ48)} -> 0 | AV54: {=IF($C54 <= AV49, AU54, INDEX('1. Données d''entrée'!$I:$K, B46 + AY50 + AV51 + $B54, AJ48))} -> 0 | AW54: {=IF($C54 <= AW$49, AU54, INDEX('1. Données d''entrée'!$I:$K, B46 + AY50 + AW51 + $B54, AJ48))} -> 0 | AX54: {=IF($C54 <= AX$49, AU54, INDEX('1. Données d''entrée'!$I:$K, B46 + AY50 + AX51 + $B54, AJ48))} -> 0 | AZ54: {=INDEX('1. Données d''entrée'!$I:$K, B46 + BD50 + AZ51 + $B54, AJ48)} -> 0 | BA54: {=IF($C54 <= BA49, AZ54, INDEX('1. Données d''entrée'!$I:$K, B46 + BD50 + BA51 + $B54, AJ48))} -> 0 | BB54: {=IF($C54 <= BB$49, AZ54, INDEX('1. Données d''entrée'!$I:$K, B46 + BD50 + BB51 + $B54, AJ48))} -> 0 | BC54: {=IF($C54 <= BC$49, AZ54, INDEX('1. Données d''entrée'!$I:$K, B46 + BD50 + BC51 + $B54, AJ48))} -> 0 | BE54: {=INDEX('1. Données d''entrée'!$I:$K, B46 + BI50 + BE51 + $B54, AJ48)} -> 0 | BF54: {=IF($C54 <= BF49, BE54, INDEX('1. Données d''entrée'!$I:$K, B46 + BI50 + BF51 + $B54, AJ48))} -> 0 | BG54: {=IF($C54 <= BG$49, BE54, INDEX('1. Données d''entrée'!$I:$K, B46 + BI50 + BG51 + $B54, AJ48))} -> 0 | BH54: {=IF($C54 <= BH$49, BE54, INDEX('1. Données d''entrée'!$I:$K, B46 + BI50 + BH51 + $B54, AJ48))} -> 0 | BJ54: {=INDEX('1. Données d''entrée'!$I:$K, B46 + BN50 + BJ51 + $B54, AJ48)} -> 0 | BK54: {=IF($C54 <= BK49, BJ54, INDEX('1. Données d''entrée'!$I:$K, B46 + BN50 + BK51 + $B54, AJ48))} -> 0 | BL54: {=IF($C54 <= BL$49, BJ54, INDEX('1. Données d''entrée'!$I:$K, B46 + BN50 + BL51 + $B54, AJ48))} -> 0 | BM54: {=IF($C54 <= BM$49, BJ54, INDEX('1. Données d''entrée'!$I:$K, B46 + BN50 + BM51 + $B54, AJ48))} -> 0 | BQ54: {=INDEX('1. Données d''entrée'!$I:$K, B46 + BU50 + BQ51 + $B54, BP48)} -> 0 | BR54: {=IF($C54 <= BR49, BQ54, INDEX('1. Données d''entrée'!$I:$K, B46 + BU50 + BR51 + $B54, BP48))} -> 0 | BS54: {=IF($C54 <= BS$49, BQ54, INDEX('1. Données d''entrée'!$I:$K, B46 + BU50 + BS51 + $B54, BP48))} -> 0 | BT54: {=IF($C54 <= BT$49, BQ54, INDEX('1. Données d''entrée'!$I:$K, B46 + BU50 + BT51 + $B54, BP48))} -> 0 | BV54: {=INDEX('1. Données d''entrée'!$I:$K, B46 + BZ50 + BV51 + $B54, BP48)} -> 0 | BW54: {=IF($C54 <= BW49, BV54, INDEX('1. Données d''entrée'!$I:$K, B46 + BZ50 + BW51 + $B54, BP48))} -> 0 | BX54: {=IF($C54 <= BX$49, BV54, INDEX('1. Données d''entrée'!$I:$K, B46 + BZ50 + BX51 + $B54, BP48))} -> 0 | BY54: {=IF($C54 <= BY$49, BV54, INDEX('1. Données d''entrée'!$I:$K, B46 + BZ50 + BY51 + $B54, BP48))} -> 0 | CA54: {=INDEX('1. Données d''entrée'!$I:$K, B46 + CE50 + CA51 + $B54, BP48)} -> 0 | CB54: {=IF($C54 <= CB49, CA54, INDEX('1. Données d''entrée'!$I:$K, B46 + CE50 + CB51 + $B54, BP48))} -> 0 | CC54: {=IF($C54 <= CC$49, CA54, INDEX('1. Données d''entrée'!$I:$K, B46 + CE50 + CC51 + $B54, BP48))} -> 0 | CD54: {=IF($C54 <= CD$49, CA54, INDEX('1. Données d''entrée'!$I:$K, B46 + CE50 + CD51 + $B54, BP48))} -> 0 | CF54: {=INDEX('1. Données d''entrée'!$I:$K, B46 + CJ50 + CF51 + $B54, BP48)} -> 0 | CG54: {=IF($C54 <= CG49, CF54, INDEX('1. Données d''entrée'!$I:$K, B46 + CJ50 + CG51 + $B54, BP48))} -> 0 | CH54: {=IF($C54 <= CH$49, CF54, INDEX('1. Données d''entrée'!$I:$K, B46 + CJ50 + CH51 + $B54, BP48))} -> 0 | CI54: {=IF($C54 <= CI$49, CF54, INDEX('1. Données d''entrée'!$I:$K, B46 + CJ50 + CI51 + $B54, BP48))} -> 0 | CK54: {=INDEX('1. Données d''entrée'!$I:$K, B46 + CO50 + CK51 + $B54, BP48)} -> 0 | CL54: {=IF($C54 <= CL49, CK54, INDEX('1. Données d''entrée'!$I:$K, B46 + CO50 + CL51 + $B54, BP48))} -> 0 | CM54: {=IF($C54 <= CM$49, CK54, INDEX('1. Données d''entrée'!$I:$K, B46 + CO50 + CM51 + $B54, BP48))} -> 0 | CN54: {=IF($C54 <= CN$49, CK54, INDEX('1. Données d''entrée'!$I:$K, B46 + CO50 + CN51 + $B54, BP48))} -> 0 | CP54: {=INDEX('1. Données d''entrée'!$I:$K, B46 + CT50 + CP51 + $B54, BP48)} -> 0 | CQ54: {=IF($C54 <= CQ49, CP54, INDEX('1. Données d''entrée'!$I:$K, B46 + CT50 + CQ51 + $B54, BP48))} -> 0 | CR54: {=IF($C54 <= CR$49, CP54, INDEX('1. Données d''entrée'!$I:$K, B46 + CT50 + CR51 + $B54, BP48))} -> 0 | CS54: {=IF($C54 <= CS$49, CP54, INDEX('1. Données d''entrée'!$I:$K, B46 + CT50 + CS51 + $B54, BP48))} -> 0
B55: 2 | C55: 2012 | E55: {=INDEX('1. Données d''entrée'!$I:$K, B46 + I50 + E51 + $B55, D48)} -> 0 | F55: {=IF($C55 <= F49, E55, INDEX('1. Données d''entrée'!$I:$K, B46 + I50 + F51 + $B55, D48))} -> 0 | G55: {=IF($C55 <= G$49, E55, INDEX('1. Données d''entrée'!$I:$K, B46 + I50 + G51 + $B55, D48))} -> 0 | H55: {=IF($C55 <= H$49, E55, INDEX('1. Données d''entrée'!$I:$K, B46 + I50 + H51 + $B55, D48))} -> 0 | J55: {=INDEX('1. Données d''entrée'!$I:$K, B46 + N50 + J51 + $B55, D48)} -> 0 | K55: {=IF($C55 <= K49, J55, INDEX('1. Données d''entrée'!$I:$K, B46 + N50 + K51 + $B55, D48))} -> 0 | L55: {=IF($C55 <= L$49, J55, INDEX('1. Données d''entrée'!$I:$K, B46 + N50 + L51 + $B55, D48))} -> 0 | M55: {=IF($C55 <= M$49, J55, INDEX('1. Données d''entrée'!$I:$K, B46 + N50 + M51 + $B55, D48))} -> 0 | O55: {=INDEX('1. Données d''entrée'!$I:$K, B46 + S50 + O51 + $B55, D48)} -> 0 | P55: {=IF($C55 <= P49, O55, INDEX('1. Données d''entrée'!$I:$K, B46 + S50 + P51 + $B55, D48))} -> 0 | Q55: {=IF($C55 <= Q$49, O55, INDEX('1. Données d''entrée'!$I:$K, B46 + S50 + Q51 + $B55, D48))} -> 0 | R55: {=IF($C55 <= R$49, O55, INDEX('1. Données d''entrée'!$I:$K, B46 + S50 + R51 + $B55, D48))} -> 0 | T55: {=INDEX('1. Données d''entrée'!$I:$K, B46 + X50 + T51 + $B55, D48)} -> 0 | U55: {=IF($C55 <= U49, T55, INDEX('1. Données d''entrée'!$I:$K, B46 + X50 + U51 + $B55, D48))} -> 0 | V55: {=IF($C55 <= V$49, T55, INDEX('1. Données d''entrée'!$I:$K, B46 + X50 + V51 + $B55, D48))} -> 0 | W55: {=IF($C55 <= W$49, T55, INDEX('1. Données d''entrée'!$I:$K, B46 + X50 + W51 + $B55, D48))} -> 0 | Y55: {=INDEX('1. Données d''entrée'!$I:$K, B46 + AC50 + Y51 + $B55, D48)} -> 0 | Z55: {=IF($C55 <= Z49, Y55, INDEX('1. Données d''entrée'!$I:$K, B46 + AC50 + Z51 + $B55, D48))} -> 0 | AA55: {=IF($C55 <= AA$49, Y55, INDEX('1. Données d''entrée'!$I:$K, B46 + AC50 + AA51 + $B55, D48))} -> 0 | AB55: {=IF($C55 <= AB$49, Y55, INDEX('1. Données d''entrée'!$I:$K, B46 + AC50 + AB51 + $B55, D48))} -> 0 | AD55: {=INDEX('1. Données d''entrée'!$I:$K, B46 + AH50 + AD51 + $B55, D48)} -> 0 | AE55: {=IF($C55 <= AE49, AD55, INDEX('1. Données d''entrée'!$I:$K, B46 + AH50 + AE51 + $B55, D48))} -> 0 | AF55: {=IF($C55 <= AF$49, AD55, INDEX('1. Données d''entrée'!$I:$K, B46 + AH50 + AF51 + $B55, D48))} -> 0 | AG55: {=IF($C55 <= AG$49, AD55, INDEX('1. Données d''entrée'!$I:$K, B46 + AH50 + AG51 + $B55, D48))} -> 0 | AK55: {=INDEX('1. Données d''entrée'!$I:$K, B46 + AO50 + AK51 + $B55, AJ48)} -> 0 | AL55: {=IF($C55 <= AL49, AK55, INDEX('1. Données d''entrée'!$I:$K, B46 + AO50 + AL51 + $B55, AJ48))} -> 0 | AM55: {=IF($C55 <= AM$49, AK55, INDEX('1. Données d''entrée'!$I:$K, B46 + AO50 + AM51 + $B55, AJ48))} -> 0 | AN55: {=IF($C55 <= AN$49, AK55, INDEX('1. Données d''entrée'!$I:$K, B46 + AO50 + AN51 + $B55, AJ48))} -> 0 | AP55: {=INDEX('1. Données d''entrée'!$I:$K, B46 + AT50 + AP51 + $B55, AJ48)} -> 0 | AQ55: {=IF($C55 <= AQ49, AP55, INDEX('1. Données d''entrée'!$I:$K, B46 + AT50 + AQ51 + $B55, AJ48))} -> 0 | AR55: {=IF($C55 <= AR$49, AP55, INDEX('1. Données d''entrée'!$I:$K, B46 + AT50 + AR51 + $B55, AJ48))} -> 0 | AS55: {=IF($C55 <= AS$49, AP55, INDEX('1. Données d''entrée'!$I:$K, B46 + AT50 + AS51 + $B55, AJ48))} -> 0 | AU55: {=INDEX('1. Données d''entrée'!$I:$K, B46 + AY50 + AU51 + $B55, AJ48)} -> 0 | AV55: {=IF($C55 <= AV49, AU55, INDEX('1. Données d''entrée'!$I:$K, B46 + AY50 + AV51 + $B55, AJ48))} -> 0 | AW55: {=IF($C55 <= AW$49, AU55, INDEX('1. Données d''entrée'!$I:$K, B46 + AY50 + AW51 + $B55, AJ48))} -> 0 | AX55: {=IF($C55 <= AX$49, AU55, INDEX('1. Données d''entrée'!$I:$K, B46 + AY50 + AX51 + $B55, AJ48))} -> 0 | AZ55: {=INDEX('1. Données d''entrée'!$I:$K, B46 + BD50 + AZ51 + $B55, AJ48)} -> 0 | BA55: {=IF($C55 <= BA49, AZ55, INDEX('1. Données d''entrée'!$I:$K, B46 + BD50 + BA51 + $B55, AJ48))} -> 0 | BB55: {=IF($C55 <= BB$49, AZ55, INDEX('1. Données d''entrée'!$I:$K, B46 + BD50 + BB51 + $B55, AJ48))} -> 0 | BC55: {=IF($C55 <= BC$49, AZ55, INDEX('1. Données d''entrée'!$I:$K, B46 + BD50 + BC51 + $B55, AJ48))} -> 0 | BE55: {=INDEX('1. Données d''entrée'!$I:$K, B46 + BI50 + BE51 + $B55, AJ48)} -> 0 | BF55: {=IF($C55 <= BF49, BE55, INDEX('1. Données d''entrée'!$I:$K, B46 + BI50 + BF51 + $B55, AJ48))} -> 0 | BG55: {=IF($C55 <= BG$49, BE55, INDEX('1. Données d''entrée'!$I:$K, B46 + BI50 + BG51 + $B55, AJ48))} -> 0 | BH55: {=IF($C55 <= BH$49, BE55, INDEX('1. Données d''entrée'!$I:$K, B46 + BI50 + BH51 + $B55, AJ48))} -> 0 | BJ55: {=INDEX('1. Données d''entrée'!$I:$K, B46 + BN50 + BJ51 + $B55, AJ48)} -> 0 | BK55: {=IF($C55 <= BK49, BJ55, INDEX('1. Données d''entrée'!$I:$K, B46 + BN50 + BK51 + $B55, AJ48))} -> 0 | BL55: {=IF($C55 <= BL$49, BJ55, INDEX('1. Données d''entrée'!$I:$K, B46 + BN50 + BL51 + $B55, AJ48))} -> 0 | BM55: {=IF($C55 <= BM$49, BJ55, INDEX('1. Données d''entrée'!$I:$K, B46 + BN50 + BM51 + $B55, AJ48))} -> 0 | BQ55: {=INDEX('1. Données d''entrée'!$I:$K, B46 + BU50 + BQ51 + $B55, BP48)} -> 0 | BR55: {=IF($C55 <= BR49, BQ55, INDEX('1. Données d''entrée'!$I:$K, B46 + BU50 + BR51 + $B55, BP48))} -> 0 | BS55: {=IF($C55 <= BS$49, BQ55, INDEX('1. Données d''entrée'!$I:$K, B46 + BU50 + BS51 + $B55, BP48))} -> 0 | BT55: {=IF($C55 <= BT$49, BQ55, INDEX('1. Données d''entrée'!$I:$K, B46 + BU50 + BT51 + $B55, BP48))} -> 0 | BV55: {=INDEX('1. Données d''entrée'!$I:$K, B46 + BZ50 + BV51 + $B55, BP48)} -> 0 | BW55: {=IF($C55 <= BW49, BV55, INDEX('1. Données d''entrée'!$I:$K, B46 + BZ50 + BW51 + $B55, BP48))} -> 0 | BX55: {=IF($C55 <= BX$49, BV55, INDEX('1. Données d''entrée'!$I:$K, B46 + BZ50 + BX51 + $B55, BP48))} -> 0 | BY55: {=IF($C55 <= BY$49, BV55, INDEX('1. Données d''entrée'!$I:$K, B46 + BZ50 + BY51 + $B55, BP48))} -> 0 | CA55: {=INDEX('1. Données d''entrée'!$I:$K, B46 + CE50 + CA51 + $B55, BP48)} -> 0 | CB55: {=IF($C55 <= CB49, CA55, INDEX('1. Données d''entrée'!$I:$K, B46 + CE50 + CB51 + $B55, BP48))} -> 0 | CC55: {=IF($C55 <= CC$49, CA55, INDEX('1. Données d''entrée'!$I:$K, B46 + CE50 + CC51 + $B55, BP48))} -> 0 | CD55: {=IF($C55 <= CD$49, CA55, INDEX('1. Données d''entrée'!$I:$K, B46 + CE50 + CD51 + $B55, BP48))} -> 0 | CF55: {=INDEX('1. Données d''entrée'!$I:$K, B46 + CJ50 + CF51 + $B55, BP48)} -> 0 | CG55: {=IF($C55 <= CG49, CF55, INDEX('1. Données d''entrée'!$I:$K, B46 + CJ50 + CG51 + $B55, BP48))} -> 0 | CH55: {=IF($C55 <= CH$49, CF55, INDEX('1. Données d''entrée'!$I:$K, B46 + CJ50 + CH51 + $B55, BP48))} -> 0 | CI55: {=IF($C55 <= CI$49, CF55, INDEX('1. Données d''entrée'!$I:$K, B46 + CJ50 + CI51 + $B55, BP48))} -> 0 | CK55: {=INDEX('1. Données d''entrée'!$I:$K, B46 + CO50 + CK51 + $B55, BP48)} -> 0 | CL55: {=IF($C55 <= CL49, CK55, INDEX('1. Données d''entrée'!$I:$K, B46 + CO50 + CL51 + $B55, BP48))} -> 0 | CM55: {=IF($C55 <= CM$49, CK55, INDEX('1. Données d''entrée'!$I:$K, B46 + CO50 + CM51 + $B55, BP48))} -> 0 | CN55: {=IF($C55 <= CN$49, CK55, INDEX('1. Données d''entrée'!$I:$K, B46 + CO50 + CN51 + $B55, BP48))} -> 0 | CP55: {=INDEX('1. Données d''entrée'!$I:$K, B46 + CT50 + CP51 + $B55, BP48)} -> 0 | CQ55: {=IF($C55 <= CQ49, CP55, INDEX('1. Données d''entrée'!$I:$K, B46 + CT50 + CQ51 + $B55, BP48))} -> 0 | CR55: {=IF($C55 <= CR$49, CP55, INDEX('1. Données d''entrée'!$I:$K, B46 + CT50 + CR51 + $B55, BP48))} -> 0 | CS55: {=IF($C55 <= CS$49, CP55, INDEX('1. Données d''entrée'!$I:$K, B46 + CT50 + CS51 + $B55, BP48))} -> 0
B56: 3 | C56: 2013 | E56: {=INDEX('1. Données d''entrée'!$I:$K, B46 + I50 + E51 + $B56, D48)} -> 0 | F56: {=IF($C56 <= F49, E56, INDEX('1. Données d''entrée'!$I:$K, B46 + I50 + F51 + $B56, D48))} -> 0 | G56: {=IF($C56 <= G$49, E56, INDEX('1. Données d''entrée'!$I:$K, B46 + I50 + G51 + $B56, D48))} -> 0 | H56: {=IF($C56 <= H$49, E56, INDEX('1. Données d''entrée'!$I:$K, B46 + I50 + H51 + $B56, D48))} -> 0 | J56: {=INDEX('1. Données d''entrée'!$I:$K, B46 + N50 + J51 + $B56, D48)} -> 0 | K56: {=IF($C56 <= K49, J56, INDEX('1. Données d''entrée'!$I:$K, B46 + N50 + K51 + $B56, D48))} -> 0 | L56: {=IF($C56 <= L$49, J56, INDEX('1. Données d''entrée'!$I:$K, B46 + N50 + L51 + $B56, D48))} -> 0 | M56: {=IF($C56 <= M$49, J56, INDEX('1. Données d''entrée'!$I:$K, B46 + N50 + M51 + $B56, D48))} -> 0 | O56: {=INDEX('1. Données d''entrée'!$I:$K, B46 + S50 + O51 + $B56, D48)} -> 0 | P56: {=IF($C56 <= P49, O56, INDEX('1. Données d''entrée'!$I:$K, B46 + S50 + P51 + $B56, D48))} -> 0 | Q56: {=IF($C56 <= Q$49, O56, INDEX('1. Données d''entrée'!$I:$K, B46 + S50 + Q51 + $B56, D48))} -> 0 | R56: {=IF($C56 <= R$49, O56, INDEX('1. Données d''entrée'!$I:$K, B46 + S50 + R51 + $B56, D48))} -> 0 | T56: {=INDEX('1. Données d''entrée'!$I:$K, B46 + X50 + T51 + $B56, D48)} -> 0 | U56: {=IF($C56 <= U49, T56, INDEX('1. Données d''entrée'!$I:$K, B46 + X50 + U51 + $B56, D48))} -> 0 | V56: {=IF($C56 <= V$49, T56, INDEX('1. Données d''entrée'!$I:$K, B46 + X50 + V51 + $B56, D48))} -> 0 | W56: {=IF($C56 <= W$49, T56, INDEX('1. Données d''entrée'!$I:$K, B46 + X50 + W51 + $B56, D48))} -> 0 | Y56: {=INDEX('1. Données d''entrée'!$I:$K, B46 + AC50 + Y51 + $B56, D48)} -> 0 | Z56: {=IF($C56 <= Z49, Y56, INDEX('1. Données d''entrée'!$I:$K, B46 + AC50 + Z51 + $B56, D48))} -> 0 | AA56: {=IF($C56 <= AA$49, Y56, INDEX('1. Données d''entrée'!$I:$K, B46 + AC50 + AA51 + $B56, D48))} -> 0 | AB56: {=IF($C56 <= AB$49, Y56, INDEX('1. Données d''entrée'!$I:$K, B46 + AC50 + AB51 + $B56, D48))} -> 0 | AD56: {=INDEX('1. Données d''entrée'!$I:$K, B46 + AH50 + AD51 + $B56, D48)} -> 0 | AE56: {=IF($C56 <= AE49, AD56, INDEX('1. Données d''entrée'!$I:$K, B46 + AH50 + AE51 + $B56, D48))} -> 0 | AF56: {=IF($C56 <= AF$49, AD56, INDEX('1. Données d''entrée'!$I:$K, B46 + AH50 + AF51 + $B56, D48))} -> 0 | AG56: {=IF($C56 <= AG$49, AD56, INDEX('1. Données d''entrée'!$I:$K, B46 + AH50 + AG51 + $B56, D48))} -> 0 | AK56: {=INDEX('1. Données d''entrée'!$I:$K, B46 + AO50 + AK51 + $B56, AJ48)} -> 0 | AL56: {=IF($C56 <= AL49, AK56, INDEX('1. Données d''entrée'!$I:$K, B46 + AO50 + AL51 + $B56, AJ48))} -> 0 | AM56: {=IF($C56 <= AM$49, AK56, INDEX('1. Données d''entrée'!$I:$K, B46 + AO50 + AM51 + $B56, AJ48))} -> 0 | AN56: {=IF($C56 <= AN$49, AK56, INDEX('1. Données d''entrée'!$I:$K, B46 + AO50 + AN51 + $B56, AJ48))} -> 0 | AP56: {=INDEX('1. Données d''entrée'!$I:$K, B46 + AT50 + AP51 + $B56, AJ48)} -> 0 | AQ56: {=IF($C56 <= AQ49, AP56, INDEX('1. Données d''entrée'!$I:$K, B46 + AT50 + AQ51 + $B56, AJ48))} -> 0 | AR56: {=IF($C56 <= AR$49, AP56, INDEX('1. Données d''entrée'!$I:$K, B46 + AT50 + AR51 + $B56, AJ48))} -> 0 | AS56: {=IF($C56 <= AS$49, AP56, INDEX('1. Données d''entrée'!$I:$K, B46 + AT50 + AS51 + $B56, AJ48))} -> 0 | AU56: {=INDEX('1. Données d''entrée'!$I:$K, B46 + AY50 + AU51 + $B56, AJ48)} -> 0 | AV56: {=IF($C56 <= AV49, AU56, INDEX('1. Données d''entrée'!$I:$K, B46 + AY50 + AV51 + $B56, AJ48))} -> 0 | AW56: {=IF($C56 <= AW$49, AU56, INDEX('1. Données d''entrée'!$I:$K, B46 + AY50 + AW51 + $B56, AJ48))} -> 0 | AX56: {=IF($C56 <= AX$49, AU56, INDEX('1. Données d''entrée'!$I:$K, B46 + AY50 + AX51 + $B56, AJ48))} -> 0 | AZ56: {=INDEX('1. Données d''entrée'!$I:$K, B46 + BD50 + AZ51 + $B56, AJ48)} -> 0 | BA56: {=IF($C56 <= BA49, AZ56, INDEX('1. Données d''entrée'!$I:$K, B46 + BD50 + BA51 + $B56, AJ48))} -> 0 | BB56: {=IF($C56 <= BB$49, AZ56, INDEX('1. Données d''entrée'!$I:$K, B46 + BD50 + BB51 + $B56, AJ48))} -> 0 | BC56: {=IF($C56 <= BC$49, AZ56, INDEX('1. Données d''entrée'!$I:$K, B46 + BD50 + BC51 + $B56, AJ48))} -> 0 | BE56: {=INDEX('1. Données d''entrée'!$I:$K, B46 + BI50 + BE51 + $B56, AJ48)} -> 0 | BF56: {=IF($C56 <= BF49, BE56, INDEX('1. Données d''entrée'!$I:$K, B46 + BI50 + BF51 + $B56, AJ48))} -> 0 | BG56: {=IF($C56 <= BG$49, BE56, INDEX('1. Données d''entrée'!$I:$K, B46 + BI50 + BG51 + $B56, AJ48))} -> 0 | BH56: {=IF($C56 <= BH$49, BE56, INDEX('1. Données d''entrée'!$I:$K, B46 + BI50 + BH51 + $B56, AJ48))} -> 0 | BJ56: {=INDEX('1. Données d''entrée'!$I:$K, B46 + BN50 + BJ51 + $B56, AJ48)} -> 0 | BK56: {=IF($C56 <= BK49, BJ56, INDEX('1. Données d''entrée'!$I:$K, B46 + BN50 + BK51 + $B56, AJ48))} -> 0 | BL56: {=IF($C56 <= BL$49, BJ56, INDEX('1. Données d''entrée'!$I:$K, B46 + BN50 + BL51 + $B56, AJ48))} -> 0 | BM56: {=IF($C56 <= BM$49, BJ56, INDEX('1. Données d''entrée'!$I:$K, B46 + BN50 + BM51 + $B56, AJ48))} -> 0 | BQ56: {=INDEX('1. Données d''entrée'!$I:$K, B46 + BU50 + BQ51 + $B56, BP48)} -> 0 | BR56: {=IF($C56 <= BR49, BQ56, INDEX('1. Données d''entrée'!$I:$K, B46 + BU50 + BR51 + $B56, BP48))} -> 0 | BS56: {=IF($C56 <= BS$49, BQ56, INDEX('1. Données d''entrée'!$I:$K, B46 + BU50 + BS51 + $B56, BP48))} -> 0 | BT56: {=IF($C56 <= BT$49, BQ56, INDEX('1. Données d''entrée'!$I:$K, B46 + BU50 + BT51 + $B56, BP48))} -> 0 | BV56: {=INDEX('1. Données d''entrée'!$I:$K, B46 + BZ50 + BV51 + $B56, BP48)} -> 0 | BW56: {=IF($C56 <= BW49, BV56, INDEX('1. Données d''entrée'!$I:$K, B46 + BZ50 + BW51 + $B56, BP48))} -> 0 | BX56: {=IF($C56 <= BX$49, BV56, INDEX('1. Données d''entrée'!$I:$K, B46 + BZ50 + BX51 + $B56, BP48))} -> 0 | BY56: {=IF($C56 <= BY$49, BV56, INDEX('1. Données d''entrée'!$I:$K, B46 + BZ50 + BY51 + $B56, BP48))} -> 0 | CA56: {=INDEX('1. Données d''entrée'!$I:$K, B46 + CE50 + CA51 + $B56, BP48)} -> 0 | CB56: {=IF($C56 <= CB49, CA56, INDEX('1. Données d''entrée'!$I:$K, B46 + CE50 + CB51 + $B56, BP48))} -> 0 | CC56: {=IF($C56 <= CC$49, CA56, INDEX('1. Données d''entrée'!$I:$K, B46 + CE50 + CC51 + $B56, BP48))} -> 0 | CD56: {=IF($C56 <= CD$49, CA56, INDEX('1. Données d''entrée'!$I:$K, B46 + CE50 + CD51 + $B56, BP48))} -> 0 | CF56: {=INDEX('1. Données d''entrée'!$I:$K, B46 + CJ50 + CF51 + $B56, BP48)} -> 0 | CG56: {=IF($C56 <= CG49, CF56, INDEX('1. Données d''entrée'!$I:$K, B46 + CJ50 + CG51 + $B56, BP48))} -> 0 | CH56: {=IF($C56 <= CH$49, CF56, INDEX('1. Données d''entrée'!$I:$K, B46 + CJ50 + CH51 + $B56, BP48))} -> 0 | CI56: {=IF($C56 <= CI$49, CF56, INDEX('1. Données d''entrée'!$I:$K, B46 + CJ50 + CI51 + $B56, BP48))} -> 0 | CK56: {=INDEX('1. Données d''entrée'!$I:$K, B46 + CO50 + CK51 + $B56, BP48)} -> 0 | CL56: {=IF($C56 <= CL49, CK56, INDEX('1. Données d''entrée'!$I:$K, B46 + CO50 + CL51 + $B56, BP48))} -> 0 | CM56: {=IF($C56 <= CM$49, CK56, INDEX('1. Données d''entrée'!$I:$K, B46 + CO50 + CM51 + $B56, BP48))} -> 0 | CN56: {=IF($C56 <= CN$49, CK56, INDEX('1. Données d''entrée'!$I:$K, B46 + CO50 + CN51 + $B56, BP48))} -> 0 | CP56: {=INDEX('1. Données d''entrée'!$I:$K, B46 + CT50 + CP51 + $B56, BP48)} -> 0 | CQ56: {=IF($C56 <= CQ49, CP56, INDEX('1. Données d''entrée'!$I:$K, B46 + CT50 + CQ51 + $B56, BP48))} -> 0 | CR56: {=IF($C56 <= CR$49, CP56, INDEX('1. Données d''entrée'!$I:$K, B46 + CT50 + CR51 + $B56, BP48))} -> 0 | CS56: {=IF($C56 <= CS$49, CP56, INDEX('1. Données d''entrée'!$I:$K, B46 + CT50 + CS51 + $B56, BP48))} -> 0
B57: 4 | C57: 2014 | E57: {=INDEX('1. Données d''entrée'!$I:$K, B46 + I50 + E51 + $B57, D48)} -> 0 | F57: {=IF($C57 <= F49, E57, INDEX('1. Données d''entrée'!$I:$K, B46 + I50 + F51 + $B57, D48))} -> 0 | G57: {=IF($C57 <= G$49, E57, INDEX('1. Données d''entrée'!$I:$K, B46 + I50 + G51 + $B57, D48))} -> 0 | H57: {=IF($C57 <= H$49, E57, INDEX('1. Données d''entrée'!$I:$K, B46 + I50 + H51 + $B57, D48))} -> 0 | J57: {=INDEX('1. Données d''entrée'!$I:$K, B46 + N50 + J51 + $B57, D48)} -> 0 | K57: {=IF($C57 <= K49, J57, INDEX('1. Données d''entrée'!$I:$K, B46 + N50 + K51 + $B57, D48))} -> 0 | L57: {=IF($C57 <= L$49, J57, INDEX('1. Données d''entrée'!$I:$K, B46 + N50 + L51 + $B57, D48))} -> 0 | M57: {=IF($C57 <= M$49, J57, INDEX('1. Données d''entrée'!$I:$K, B46 + N50 + M51 + $B57, D48))} -> 0 | O57: {=INDEX('1. Données d''entrée'!$I:$K, B46 + S50 + O51 + $B57, D48)} -> 0 | P57: {=IF($C57 <= P49, O57, INDEX('1. Données d''entrée'!$I:$K, B46 + S50 + P51 + $B57, D48))} -> 0 | Q57: {=IF($C57 <= Q$49, O57, INDEX('1. Données d''entrée'!$I:$K, B46 + S50 + Q51 + $B57, D48))} -> 0 | R57: {=IF($C57 <= R$49, O57, INDEX('1. Données d''entrée'!$I:$K, B46 + S50 + R51 + $B57, D48))} -> 0 | T57: {=INDEX('1. Données d''entrée'!$I:$K, B46 + X50 + T51 + $B57, D48)} -> 0 | U57: {=IF($C57 <= U49, T57, INDEX('1. Données d''entrée'!$I:$K, B46 + X50 + U51 + $B57, D48))} -> 0 | V57: {=IF($C57 <= V$49, T57, INDEX('1. Données d''entrée'!$I:$K, B46 + X50 + V51 + $B57, D48))} -> 0 | W57: {=IF($C57 <= W$49, T57, INDEX('1. Données d''entrée'!$I:$K, B46 + X50 + W51 + $B57, D48))} -> 0 | Y57: {=INDEX('1. Données d''entrée'!$I:$K, B46 + AC50 + Y51 + $B57, D48)} -> 0 | Z57: {=IF($C57 <= Z49, Y57, INDEX('1. Données d''entrée'!$I:$K, B46 + AC50 + Z51 + $B57, D48))} -> 0 | AA57: {=IF($C57 <= AA$49, Y57, INDEX('1. Données d''entrée'!$I:$K, B46 + AC50 + AA51 + $B57, D48))} -> 0 | AB57: {=IF($C57 <= AB$49, Y57, INDEX('1. Données d''entrée'!$I:$K, B46 + AC50 + AB51 + $B57, D48))} -> 0 | AD57: {=INDEX('1. Données d''entrée'!$I:$K, B46 + AH50 + AD51 + $B57, D48)} -> 0 | AE57: {=IF($C57 <= AE49, AD57, INDEX('1. Données d''entrée'!$I:$K, B46 + AH50 + AE51 + $B57, D48))} -> 0 | AF57: {=IF($C57 <= AF$49, AD57, INDEX('1. Données d''entrée'!$I:$K, B46 + AH50 + AF51 + $B57, D48))} -> 0 | AG57: {=IF($C57 <= AG$49, AD57, INDEX('1. Données d''entrée'!$I:$K, B46 + AH50 + AG51 + $B57, D48))} -> 0 | AK57: {=INDEX('1. Données d''entrée'!$I:$K, B46 + AO50 + AK51 + $B57, AJ48)} -> 0 | AL57: {=IF($C57 <= AL49, AK57, INDEX('1. Données d''entrée'!$I:$K, B46 + AO50 + AL51 + $B57, AJ48))} -> 0 | AM57: {=IF($C57 <= AM$49, AK57, INDEX('1. Données d''entrée'!$I:$K, B46 + AO50 + AM51 + $B57, AJ48))} -> 0 | AN57: {=IF($C57 <= AN$49, AK57, INDEX('1. Données d''entrée'!$I:$K, B46 + AO50 + AN51 + $B57, AJ48))} -> 0 | AP57: {=INDEX('1. Données d''entrée'!$I:$K, B46 + AT50 + AP51 + $B57, AJ48)} -> 0 | AQ57: {=IF($C57 <= AQ49, AP57, INDEX('1. Données d''entrée'!$I:$K, B46 + AT50 + AQ51 + $B57, AJ48))} -> 0 | AR57: {=IF($C57 <= AR$49, AP57, INDEX('1. Données d''entrée'!$I:$K, B46 + AT50 + AR51 + $B57, AJ48))} -> 0 | AS57: {=IF($C57 <= AS$49, AP57, INDEX('1. Données d''entrée'!$I:$K, B46 + AT50 + AS51 + $B57, AJ48))} -> 0 | AU57: {=INDEX('1. Données d''entrée'!$I:$K, B46 + AY50 + AU51 + $B57, AJ48)} -> 0 | AV57: {=IF($C57 <= AV49, AU57, INDEX('1. Données d''entrée'!$I:$K, B46 + AY50 + AV51 + $B57, AJ48))} -> 0 | AW57: {=IF($C57 <= AW$49, AU57, INDEX('1. Données d''entrée'!$I:$K, B46 + AY50 + AW51 + $B57, AJ48))} -> 0 | AX57: {=IF($C57 <= AX$49, AU57, INDEX('1. Données d''entrée'!$I:$K, B46 + AY50 + AX51 + $B57, AJ48))} -> 0 | AZ57: {=INDEX('1. Données d''entrée'!$I:$K, B46 + BD50 + AZ51 + $B57, AJ48)} -> 0 | BA57: {=IF($C57 <= BA49, AZ57, INDEX('1. Données d''entrée'!$I:$K, B46 + BD50 + BA51 + $B57, AJ48))} -> 0 | BB57: {=IF($C57 <= BB$49, AZ57, INDEX('1. Données d''entrée'!$I:$K, B46 + BD50 + BB51 + $B57, AJ48))} -> 0 | BC57: {=IF($C57 <= BC$49, AZ57, INDEX('1. Données d''entrée'!$I:$K, B46 + BD50 + BC51 + $B57, AJ48))} -> 0 | BE57: {=INDEX('1. Données d''entrée'!$I:$K, B46 + BI50 + BE51 + $B57, AJ48)} -> 0 | BF57: {=IF($C57 <= BF49, BE57, INDEX('1. Données d''entrée'!$I:$K, B46 + BI50 + BF51 + $B57, AJ48))} -> 0 | BG57: {=IF($C57 <= BG$49, BE57, INDEX('1. Données d''entrée'!$I:$K, B46 + BI50 + BG51 + $B57, AJ48))} -> 0 | BH57: {=IF($C57 <= BH$49, BE57, INDEX('1. Données d''entrée'!$I:$K, B46 + BI50 + BH51 + $B57, AJ48))} -> 0 | BJ57: {=INDEX('1. Données d''entrée'!$I:$K, B46 + BN50 + BJ51 + $B57, AJ48)} -> 0 | BK57: {=IF($C57 <= BK49, BJ57, INDEX('1. Données d''entrée'!$I:$K, B46 + BN50 + BK51 + $B57, AJ48))} -> 0 | BL57: {=IF($C57 <= BL$49, BJ57, INDEX('1. Données d''entrée'!$I:$K, B46 + BN50 + BL51 + $B57, AJ48))} -> 0 | BM57: {=IF($C57 <= BM$49, BJ57, INDEX('1. Données d''entrée'!$I:$K, B46 + BN50 + BM51 + $B57, AJ48))} -> 0 | BQ57: {=INDEX('1. Données d''entrée'!$I:$K, B46 + BU50 + BQ51 + $B57, BP48)} -> 0 | BR57: {=IF($C57 <= BR49, BQ57, INDEX('1. Données d''entrée'!$I:$K, B46 + BU50 + BR51 + $B57, BP48))} -> 0 | BS57: {=IF($C57 <= BS$49, BQ57, INDEX('1. Données d''entrée'!$I:$K, B46 + BU50 + BS51 + $B57, BP48))} -> 0 | BT57: {=IF($C57 <= BT$49, BQ57, INDEX('1. Données d''entrée'!$I:$K, B46 + BU50 + BT51 + $B57, BP48))} -> 0 | BV57: {=INDEX('1. Données d''entrée'!$I:$K, B46 + BZ50 + BV51 + $B57, BP48)} -> 0 | BW57: {=IF($C57 <= BW49, BV57, INDEX('1. Données d''entrée'!$I:$K, B46 + BZ50 + BW51 + $B57, BP48))} -> 0 | BX57: {=IF($C57 <= BX$49, BV57, INDEX('1. Données d''entrée'!$I:$K, B46 + BZ50 + BX51 + $B57, BP48))} -> 0 | BY57: {=IF($C57 <= BY$49, BV57, INDEX('1. Données d''entrée'!$I:$K, B46 + BZ50 + BY51 + $B57, BP48))} -> 0 | CA57: {=INDEX('1. Données d''entrée'!$I:$K, B46 + CE50 + CA51 + $B57, BP48)} -> 0 | CB57: {=IF($C57 <= CB49, CA57, INDEX('1. Données d''entrée'!$I:$K, B46 + CE50 + CB51 + $B57, BP48))} -> 0 | CC57: {=IF($C57 <= CC$49, CA57, INDEX('1. Données d''entrée'!$I:$K, B46 + CE50 + CC51 + $B57, BP48))} -> 0 | CD57: {=IF($C57 <= CD$49, CA57, INDEX('1. Données d''entrée'!$I:$K, B46 + CE50 + CD51 + $B57, BP48))} -> 0 | CF57: {=INDEX('1. Données d''entrée'!$I:$K, B46 + CJ50 + CF51 + $B57, BP48)} -> 0 | CG57: {=IF($C57 <= CG49, CF57, INDEX('1. Données d''entrée'!$I:$K, B46 + CJ50 + CG51 + $B57, BP48))} -> 0 | CH57: {=IF($C57 <= CH$49, CF57, INDEX('1. Données d''entrée'!$I:$K, B46 + CJ50 + CH51 + $B57, BP48))} -> 0 | CI57: {=IF($C57 <= CI$49, CF57, INDEX('1. Données d''entrée'!$I:$K, B46 + CJ50 + CI51 + $B57, BP48))} -> 0 | CK57: {=INDEX('1. Données d''entrée'!$I:$K, B46 + CO50 + CK51 + $B57, BP48)} -> 0 | CL57: {=IF($C57 <= CL49, CK57, INDEX('1. Données d''entrée'!$I:$K, B46 + CO50 + CL51 + $B57, BP48))} -> 0 | CM57: {=IF($C57 <= CM$49, CK57, INDEX('1. Données d''entrée'!$I:$K, B46 + CO50 + CM51 + $B57, BP48))} -> 0 | CN57: {=IF($C57 <= CN$49, CK57, INDEX('1. Données d''entrée'!$I:$K, B46 + CO50 + CN51 + $B57, BP48))} -> 0 | CP57: {=INDEX('1. Données d''entrée'!$I:$K, B46 + CT50 + CP51 + $B57, BP48)} -> 0 | CQ57: {=IF($C57 <= CQ49, CP57, INDEX('1. Données d''entrée'!$I:$K, B46 + CT50 + CQ51 + $B57, BP48))} -> 0 | CR57: {=IF($C57 <= CR$49, CP57, INDEX('1. Données d''entrée'!$I:$K, B46 + CT50 + CR51 + $B57, BP48))} -> 0 | CS57: {=IF($C57 <= CS$49, CP57, INDEX('1. Données d''entrée'!$I:$K, B46 + CT50 + CS51 + $B57, BP48))} -> 0
...

Sheet 3. Émissions par action
C2: Extrapolation des émissions par action (interpolation linéaire par segment)
D14: B2 - Améliorez l’efficacité de vos aires de livraisons
D17: TOTAL | AJ17: VALEUR 1 | BP17: VALEUR 2 | CV17: VALEUR 3
E18: GES | J18: PM | O18: NOx | T18: HC | Y18: CO | AD18: Nrj | AK18: GES | AP18: PM | AU18: NOx | AZ18: HC | BE18: CO | BJ18: Nrj | BQ18: GES | BV18: PM | CA18: NOx | CF18: HC | CK18: CO | CP18: Nrj | CW18: GES | DB18: PM | DG18: NOx | DL18: HC | DQ18: CO | DV18: Nrj
C20: Situation → Année ↓ | E20: Initiale | F20: Référence | G20: Prévisionnelle | H20: Ex-post | J20: Initiale | K20: Référence | L20: Prévisionnelle | M20: Ex-post | O20: Initiale | P20: Référence | Q20: Prévisionnelle | R20: Ex-post | T20: Initiale | U20: Référence | V20: Prévisionnelle | W20: Ex-post | Y20: Initiale | Z20: Référence | AA20: Prévisionnelle | AB20: Ex-post | AD20: Initiale | AE20: Référence | AF20: Prévisionnelle | AG20: Ex-post | AK20: Initiale | AL20: Référence | AM20: Prévisionnelle | AN20: Ex-post | AP20: Initiale | AQ20: Référence | AR20: Prévisionnelle | AS20: Ex-post | AU20: Initiale | AV20: Référence | AW20: Prévisionnelle | AX20: Ex-post | AZ20: Initiale | BA20: Référence | BB20: Prévisionnelle | BC20: Ex-post | BE20: Initiale | BF20: Référence | BG20: Prévisionnelle | BH20: Ex-post | BJ20: Initiale | BK20: Référence | BL20: Prévisionnelle | BM20: Ex-post | BQ20: Initiale | BR20: Référence | BS20: Prévisionnelle | BT20: Ex-post | BV20: Initiale | BW20: Référence | BX20: Prévisionnelle | BY20: Ex-post | CA20: Initiale | CB20: Référence | CC20: Prévisionnelle | CD20: Ex-post | CF20: Initiale | CG20: Référence | CH20: Prévisionnelle | CI20: Ex-post | CK20: Initiale | CL20: Référence | CM20: Prévisionnelle | CN20: Ex-post | CP20: Initiale | CQ20: Référence | CR20: Prévisionnelle | CS20: Ex-post | CW20: Initiale | CX20: Référence | CY20: Prévisionnelle | CZ20: Ex-post | DB20: Initiale | DC20: Référence | DD20: Prévisionnelle | DE20: Ex-post | DG20: Initiale | DH20: Référence | DI20: Prévisionnelle | DJ20: Ex-post | DL20: Initiale | DM20: Référence | DN20: Prévisionnelle | DO20: Ex-post | DQ20: Initiale | DR20: Référence | DS20: Prévisionnelle | DT20: Ex-post | DV20: Initiale | DW20: Référence | DX20: Prévisionnelle | DY20: Ex-post
